INFO:     Will watch for changes in these directories: ['/root/rcs_api_server/app']
INFO:uvicorn.error:Will watch for changes in these directories: ['/root/rcs_api_server/app']
INFO:     Uvicorn running on http://0.0.0.0:8000 (Press CTRL+C to quit)
INFO:uvicorn.error:Uvicorn running on http://0.0.0.0:8000 (Press CTRL+C to quit)
INFO:     Started reloader process [64325] using statreload
INFO:uvicorn.error:Started reloader process [64325] using statreload
INFO:     Started server process [64328]
INFO:uvicorn.error:Started server process [64328]
INFO:     Waiting for application startup.
INFO:uvicorn.error:Waiting for application startup.
2021-12-24 00:15:18,491 INFO sqlalchemy.engine.Engine SHOW VARIABLES LIKE 'sql_mode'
INFO:sqlalchemy.engine.Engine:SHOW VARIABLES LIKE 'sql_mode'
2021-12-24 00:15:18,491 INFO sqlalchemy.engine.Engine [raw sql] {}
INFO:sqlalchemy.engine.Engine:[raw sql] {}
2021-12-24 00:15:18,494 INFO sqlalchemy.engine.Engine SHOW VARIABLES LIKE 'lower_case_table_names'
INFO:sqlalchemy.engine.Engine:SHOW VARIABLES LIKE 'lower_case_table_names'
2021-12-24 00:15:18,494 INFO sqlalchemy.engine.Engine [generated in 0.00019s] {}
INFO:sqlalchemy.engine.Engine:[generated in 0.00019s] {}
2021-12-24 00:15:18,496 INFO sqlalchemy.engine.Engine SELECT DATABASE()
INFO:sqlalchemy.engine.Engine:SELECT DATABASE()
2021-12-24 00:15:18,497 INFO sqlalchemy.engine.Engine [raw sql] {}
INFO:sqlalchemy.engine.Engine:[raw sql] {}
INFO:     Application startup complete.
INFO:uvicorn.error:Application startup complete.
INFO:     182.226.50.40:50795 - "GET /docs HTTP/1.1" 200 OK
INFO:     182.226.50.40:50795 - "GET /openapi.json HTTP/1.1" 200 OK
INFO:     221.163.189.222:42122 - "GET /docs HTTP/1.1" 200 OK
INFO:     221.163.189.222:42122 - "GET /openapi.json HTTP/1.1" 200 OK
INFO:     221.163.189.222:35740 - "GET /docs HTTP/1.1" 200 OK
INFO:     221.163.189.222:35740 - "GET /openapi.json HTTP/1.1" 200 OK
INFO:     185.216.140.186:52116 - "GET http%3A//www.baidu.com/cache/global/img/gs.gif HTTP/1.1" 404 Not Found
INFO:     185.220.100.240:20360 - "GET / HTTP/1.1" 200 OK
INFO:     192.42.116.24:55154 - "GET /favicon.ico HTTP/1.1" 404 Not Found
INFO:     88.9.119.217:55558 - "GET / HTTP/1.1" 200 OK
WARNING:  Invalid HTTP request received.
Traceback (most recent call last):
  File "/usr/local/lib/python3.8/dist-packages/uvicorn/protocols/http/h11_impl.py", line 136, in handle_events
    event = self.conn.next_event()
  File "/usr/local/lib/python3.8/dist-packages/h11/_connection.py", line 443, in next_event
    exc._reraise_as_remote_protocol_error()
  File "/usr/local/lib/python3.8/dist-packages/h11/_util.py", line 76, in _reraise_as_remote_protocol_error
    raise self
  File "/usr/local/lib/python3.8/dist-packages/h11/_connection.py", line 425, in next_event
    event = self._extract_next_receive_event()
  File "/usr/local/lib/python3.8/dist-packages/h11/_connection.py", line 367, in _extract_next_receive_event
    event = self._reader(self._receive_buffer)
  File "/usr/local/lib/python3.8/dist-packages/h11/_readers.py", line 68, in maybe_read_from_IDLE_client
    raise LocalProtocolError("illegal request line")
h11._util.RemoteProtocolError: illegal request line
WARNING:uvicorn.error:Invalid HTTP request received.
Traceback (most recent call last):
  File "/usr/local/lib/python3.8/dist-packages/uvicorn/protocols/http/h11_impl.py", line 136, in handle_events
    event = self.conn.next_event()
  File "/usr/local/lib/python3.8/dist-packages/h11/_connection.py", line 443, in next_event
    exc._reraise_as_remote_protocol_error()
  File "/usr/local/lib/python3.8/dist-packages/h11/_util.py", line 76, in _reraise_as_remote_protocol_error
    raise self
  File "/usr/local/lib/python3.8/dist-packages/h11/_connection.py", line 425, in next_event
    event = self._extract_next_receive_event()
  File "/usr/local/lib/python3.8/dist-packages/h11/_connection.py", line 367, in _extract_next_receive_event
    event = self._reader(self._receive_buffer)
  File "/usr/local/lib/python3.8/dist-packages/h11/_readers.py", line 68, in maybe_read_from_IDLE_client
    raise LocalProtocolError("illegal request line")
h11._util.RemoteProtocolError: illegal request line
INFO:     34.238.136.197:51288 - "GET / HTTP/1.1" 200 OK
INFO:     Shutting down
INFO:uvicorn.error:Shutting down
INFO:     Finished server process [64328]
INFO:uvicorn.error:Finished server process [64328]
INFO:     ASGI 'lifespan' protocol appears unsupported.
INFO:uvicorn.error:ASGI 'lifespan' protocol appears unsupported.
INFO:     Stopping reloader process [64325]
INFO:uvicorn.error:Stopping reloader process [64325]
INFO:     Will watch for changes in these directories: ['/root/rcs_api_server/app']
INFO:uvicorn.error:Will watch for changes in these directories: ['/root/rcs_api_server/app']
INFO:     Uvicorn running on http://0.0.0.0:8000 (Press CTRL+C to quit)
INFO:uvicorn.error:Uvicorn running on http://0.0.0.0:8000 (Press CTRL+C to quit)
INFO:     Started reloader process [1601] using statreload
INFO:uvicorn.error:Started reloader process [1601] using statreload
INFO:     Started server process [1604]
INFO:uvicorn.error:Started server process [1604]
INFO:     Waiting for application startup.
INFO:uvicorn.error:Waiting for application startup.
2021-12-29 14:34:41,644 INFO sqlalchemy.engine.Engine SHOW VARIABLES LIKE 'sql_mode'
INFO:sqlalchemy.engine.Engine:SHOW VARIABLES LIKE 'sql_mode'
2021-12-29 14:34:41,644 INFO sqlalchemy.engine.Engine [raw sql] {}
INFO:sqlalchemy.engine.Engine:[raw sql] {}
2021-12-29 14:34:41,647 INFO sqlalchemy.engine.Engine SHOW VARIABLES LIKE 'lower_case_table_names'
INFO:sqlalchemy.engine.Engine:SHOW VARIABLES LIKE 'lower_case_table_names'
2021-12-29 14:34:41,647 INFO sqlalchemy.engine.Engine [generated in 0.00014s] {}
INFO:sqlalchemy.engine.Engine:[generated in 0.00014s] {}
2021-12-29 14:34:41,649 INFO sqlalchemy.engine.Engine SELECT DATABASE()
INFO:sqlalchemy.engine.Engine:SELECT DATABASE()
2021-12-29 14:34:41,649 INFO sqlalchemy.engine.Engine [raw sql] {}
INFO:sqlalchemy.engine.Engine:[raw sql] {}
INFO:     Application startup complete.
INFO:uvicorn.error:Application startup complete.
INFO:     110.10.27.29:61899 - "GET / HTTP/1.1" 200 OK
INFO:     110.10.27.29:61899 - "GET /favicon.ico HTTP/1.1" 404 Not Found
INFO:     110.10.27.29:61899 - "GET /docs HTTP/1.1" 200 OK
INFO:     110.10.27.29:61899 - "GET /openapi.json HTTP/1.1" 200 OK
INFO:     115.145.177.104:59060 - "GET /docs HTTP/1.1" 200 OK
INFO:     115.145.177.104:59060 - "GET /openapi.json HTTP/1.1" 200 OK
INFO:     110.10.27.29:62107 - "GET /docs HTTP/1.1" 200 OK
INFO:     110.10.27.29:62107 - "GET /openapi.json HTTP/1.1" 200 OK
INFO:     Shutting down
INFO:uvicorn.error:Shutting down
INFO:     Finished server process [1604]
INFO:uvicorn.error:Finished server process [1604]
INFO:     ASGI 'lifespan' protocol appears unsupported.
INFO:uvicorn.error:ASGI 'lifespan' protocol appears unsupported.
INFO:     Stopping reloader process [1601]
INFO:uvicorn.error:Stopping reloader process [1601]
INFO:     Will watch for changes in these directories: ['/root/rcs_api_server/app']
INFO:uvicorn.error:Will watch for changes in these directories: ['/root/rcs_api_server/app']
INFO:     Uvicorn running on http://0.0.0.0:8000 (Press CTRL+C to quit)
INFO:uvicorn.error:Uvicorn running on http://0.0.0.0:8000 (Press CTRL+C to quit)
INFO:     Started reloader process [2954] using statreload
INFO:uvicorn.error:Started reloader process [2954] using statreload
INFO:     Started server process [2958]
INFO:uvicorn.error:Started server process [2958]
INFO:     Waiting for application startup.
INFO:uvicorn.error:Waiting for application startup.
2021-12-29 15:06:42,139 INFO sqlalchemy.engine.Engine SHOW VARIABLES LIKE 'sql_mode'
INFO:sqlalchemy.engine.Engine:SHOW VARIABLES LIKE 'sql_mode'
2021-12-29 15:06:42,139 INFO sqlalchemy.engine.Engine [raw sql] {}
INFO:sqlalchemy.engine.Engine:[raw sql] {}
2021-12-29 15:06:42,142 INFO sqlalchemy.engine.Engine SHOW VARIABLES LIKE 'lower_case_table_names'
INFO:sqlalchemy.engine.Engine:SHOW VARIABLES LIKE 'lower_case_table_names'
2021-12-29 15:06:42,143 INFO sqlalchemy.engine.Engine [generated in 0.00023s] {}
INFO:sqlalchemy.engine.Engine:[generated in 0.00023s] {}
2021-12-29 15:06:42,145 INFO sqlalchemy.engine.Engine SELECT DATABASE()
INFO:sqlalchemy.engine.Engine:SELECT DATABASE()
2021-12-29 15:06:42,145 INFO sqlalchemy.engine.Engine [raw sql] {}
INFO:sqlalchemy.engine.Engine:[raw sql] {}
INFO:     Application startup complete.
INFO:uvicorn.error:Application startup complete.
INFO:     110.10.27.29:51453 - "GET /docs HTTP/1.1" 200 OK
INFO:     110.10.27.29:51453 - "GET /openapi.json HTTP/1.1" 200 OK
INFO:     115.145.177.104:62123 - "GET /docs HTTP/1.1" 200 OK
INFO:     115.145.177.104:62123 - "GET /openapi.json HTTP/1.1" 200 OK
INFO:     115.145.177.104:62130 - "GET /docs HTTP/1.1" 200 OK
INFO:     115.145.177.104:62130 - "GET /openapi.json HTTP/1.1" 200 OK
INFO:     115.145.177.104:62131 - "GET /docs HTTP/1.1" 200 OK
INFO:     115.145.177.104:62131 - "GET /openapi.json HTTP/1.1" 200 OK
INFO:     115.145.177.104:62158 - "GET /docs HTTP/1.1" 200 OK
INFO:     115.145.177.104:62158 - "GET /openapi.json HTTP/1.1" 200 OK
WARNING:  StatReload detected file change in 'models.py'. Reloading...
WARNING:uvicorn.error:StatReload detected file change in 'models.py'. Reloading...
INFO:     Shutting down
INFO:uvicorn.error:Shutting down
INFO:     Waiting for application shutdown.
INFO:uvicorn.error:Waiting for application shutdown.
INFO:     Application shutdown complete.
INFO:uvicorn.error:Application shutdown complete.
INFO:     Finished server process [2958]
INFO:uvicorn.error:Finished server process [2958]
INFO:     Started server process [3071]
INFO:uvicorn.error:Started server process [3071]
INFO:     Waiting for application startup.
INFO:uvicorn.error:Waiting for application startup.
2021-12-29 15:12:05,226 INFO sqlalchemy.engine.Engine SHOW VARIABLES LIKE 'sql_mode'
INFO:sqlalchemy.engine.Engine:SHOW VARIABLES LIKE 'sql_mode'
2021-12-29 15:12:05,226 INFO sqlalchemy.engine.Engine [raw sql] {}
INFO:sqlalchemy.engine.Engine:[raw sql] {}
2021-12-29 15:12:05,229 INFO sqlalchemy.engine.Engine SHOW VARIABLES LIKE 'lower_case_table_names'
INFO:sqlalchemy.engine.Engine:SHOW VARIABLES LIKE 'lower_case_table_names'
2021-12-29 15:12:05,229 INFO sqlalchemy.engine.Engine [generated in 0.00024s] {}
INFO:sqlalchemy.engine.Engine:[generated in 0.00024s] {}
2021-12-29 15:12:05,232 INFO sqlalchemy.engine.Engine SELECT DATABASE()
INFO:sqlalchemy.engine.Engine:SELECT DATABASE()
2021-12-29 15:12:05,232 INFO sqlalchemy.engine.Engine [raw sql] {}
INFO:sqlalchemy.engine.Engine:[raw sql] {}
INFO:     Application startup complete.
INFO:uvicorn.error:Application startup complete.
WARNING:  StatReload detected file change in 'routes/set_data.py'. Reloading...
WARNING:uvicorn.error:StatReload detected file change in 'routes/set_data.py'. Reloading...
INFO:     Shutting down
INFO:uvicorn.error:Shutting down
INFO:     Waiting for application shutdown.
INFO:uvicorn.error:Waiting for application shutdown.
INFO:     Application shutdown complete.
INFO:uvicorn.error:Application shutdown complete.
INFO:     Finished server process [3071]
INFO:uvicorn.error:Finished server process [3071]
Traceback (most recent call last):
  File "<string>", line 1, in <module>
  File "/usr/lib/python3.8/multiprocessing/spawn.py", line 116, in spawn_main
    exitcode = _main(fd, parent_sentinel)
  File "/usr/lib/python3.8/multiprocessing/spawn.py", line 125, in _main
    prepare(preparation_data)
  File "/usr/lib/python3.8/multiprocessing/spawn.py", line 236, in prepare
    _fixup_main_from_path(data['init_main_from_path'])
  File "/usr/lib/python3.8/multiprocessing/spawn.py", line 287, in _fixup_main_from_path
    main_content = runpy.run_path(main_path,
  File "/usr/lib/python3.8/runpy.py", line 262, in run_path
    return _run_module_code(code, init_globals, run_name,
  File "/usr/lib/python3.8/runpy.py", line 95, in _run_module_code
    _run_code(code, mod_globals, init_globals,
  File "/usr/lib/python3.8/runpy.py", line 85, in _run_code
    exec(code, run_globals)
  File "/root/rcs_api_server/app/main.py", line 7, in <module>
    from routes import index, auth, register, get, set_data
  File "/root/rcs_api_server/app/routes/set_data.py", line 59
    'robot_param': command.robot_param
    ^
SyntaxError: invalid syntax
INFO:     Stopping reloader process [2954]
INFO:uvicorn.error:Stopping reloader process [2954]
Traceback (most recent call last):
  File "main.py", line 7, in <module>
    from routes import index, auth, register, get, set_data
  File "/root/rcs_api_server/app/routes/set_data.py", line 59
    'robot_param': command.robot_param
    ^
SyntaxError: invalid syntax
INFO:     Will watch for changes in these directories: ['/root/rcs_api_server/app']
INFO:uvicorn.error:Will watch for changes in these directories: ['/root/rcs_api_server/app']
INFO:     Uvicorn running on http://0.0.0.0:8000 (Press CTRL+C to quit)
INFO:uvicorn.error:Uvicorn running on http://0.0.0.0:8000 (Press CTRL+C to quit)
INFO:     Started reloader process [3836] using statreload
INFO:uvicorn.error:Started reloader process [3836] using statreload
INFO:     Started server process [3849]
INFO:uvicorn.error:Started server process [3849]
INFO:     Waiting for application startup.
INFO:uvicorn.error:Waiting for application startup.
2021-12-29 15:49:45,954 INFO sqlalchemy.engine.Engine SHOW VARIABLES LIKE 'sql_mode'
INFO:sqlalchemy.engine.Engine:SHOW VARIABLES LIKE 'sql_mode'
2021-12-29 15:49:45,955 INFO sqlalchemy.engine.Engine [raw sql] {}
INFO:sqlalchemy.engine.Engine:[raw sql] {}
2021-12-29 15:49:45,958 INFO sqlalchemy.engine.Engine SHOW VARIABLES LIKE 'lower_case_table_names'
INFO:sqlalchemy.engine.Engine:SHOW VARIABLES LIKE 'lower_case_table_names'
2021-12-29 15:49:45,958 INFO sqlalchemy.engine.Engine [generated in 0.00026s] {}
INFO:sqlalchemy.engine.Engine:[generated in 0.00026s] {}
2021-12-29 15:49:45,960 INFO sqlalchemy.engine.Engine SELECT DATABASE()
INFO:sqlalchemy.engine.Engine:SELECT DATABASE()
2021-12-29 15:49:45,961 INFO sqlalchemy.engine.Engine [raw sql] {}
INFO:sqlalchemy.engine.Engine:[raw sql] {}
INFO:     Application startup complete.
INFO:uvicorn.error:Application startup complete.
INFO:     110.10.27.29:49890 - "GET /docs HTTP/1.1" 200 OK
INFO:     110.10.27.29:49890 - "GET /openapi.json HTTP/1.1" 200 OK
INFO:     115.145.177.104:46562 - "GET / HTTP/1.1" 200 OK
INFO:     115.145.177.104:46562 - "GET /docs HTTP/1.1" 200 OK
INFO:     115.145.177.104:46562 - "GET /openapi.json HTTP/1.1" 200 OK
INFO:     115.145.177.104:33864 - "GET /docs HTTP/1.1" 200 OK
INFO:     115.145.177.104:33864 - "GET /openapi.json HTTP/1.1" 200 OK
INFO:     115.145.177.104:33866 - "POST /set/set_command HTTP/1.1" 500 Internal Server Error
ERROR:    Exception in ASGI application
Traceback (most recent call last):
  File "/usr/local/lib/python3.8/dist-packages/uvicorn/protocols/http/h11_impl.py", line 373, in run_asgi
    result = await app(self.scope, self.receive, self.send)
  File "/usr/local/lib/python3.8/dist-packages/uvicorn/middleware/proxy_headers.py", line 75, in __call__
    return await self.app(scope, receive, send)
  File "/usr/local/lib/python3.8/dist-packages/fastapi/applications.py", line 208, in __call__
    await super().__call__(scope, receive, send)
  File "/usr/local/lib/python3.8/dist-packages/starlette/applications.py", line 112, in __call__
    await self.middleware_stack(scope, receive, send)
  File "/usr/local/lib/python3.8/dist-packages/starlette/middleware/errors.py", line 181, in __call__
    raise exc from None
  File "/usr/local/lib/python3.8/dist-packages/starlette/middleware/errors.py", line 159, in __call__
    await self.app(scope, receive, _send)
  File "/usr/local/lib/python3.8/dist-packages/starlette/middleware/cors.py", line 86, in __call__
    await self.simple_response(scope, receive, send, request_headers=headers)
  File "/usr/local/lib/python3.8/dist-packages/starlette/middleware/cors.py", line 142, in simple_response
    await self.app(scope, receive, send)
  File "/usr/local/lib/python3.8/dist-packages/starlette/exceptions.py", line 82, in __call__
    raise exc from None
  File "/usr/local/lib/python3.8/dist-packages/starlette/exceptions.py", line 71, in __call__
    await self.app(scope, receive, sender)
  File "/usr/local/lib/python3.8/dist-packages/starlette/routing.py", line 580, in __call__
    await route.handle(scope, receive, send)
  File "/usr/local/lib/python3.8/dist-packages/starlette/routing.py", line 241, in handle
    await self.app(scope, receive, send)
  File "/usr/local/lib/python3.8/dist-packages/starlette/routing.py", line 52, in app
    response = await func(request)
  File "/usr/local/lib/python3.8/dist-packages/fastapi/routing.py", line 226, in app
    raw_response = await run_endpoint_function(
  File "/usr/local/lib/python3.8/dist-packages/fastapi/routing.py", line 159, in run_endpoint_function
    return await dependant.call(**values)
  File "/root/rcs_api_server/app/routes/set_data.py", line 63, in set_command
    response=requests.post(url, json=command, headers=headers, timeout=2)
  File "/usr/local/lib/python3.8/dist-packages/requests/api.py", line 117, in post
    return request('post', url, data=data, json=json, **kwargs)
  File "/usr/local/lib/python3.8/dist-packages/requests/api.py", line 61, in request
    return session.request(method=method, url=url, **kwargs)
  File "/usr/local/lib/python3.8/dist-packages/requests/sessions.py", line 542, in request
    resp = self.send(prep, **send_kwargs)
  File "/usr/local/lib/python3.8/dist-packages/requests/sessions.py", line 655, in send
    r = adapter.send(request, **kwargs)
  File "/usr/local/lib/python3.8/dist-packages/requests/adapters.py", line 516, in send
    raise ConnectionError(e, request=request)
requests.exceptions.ConnectionError: HTTPConnectionPool(host='http', port=80): Max retries exceeded with url: //115.145.177.104:1827 (Caused by NewConnectionError('<urllib3.connection.HTTPConnection object at 0x7f5874cc3d00>: Failed to establish a new connection: [Errno -3] Temporary failure in name resolution'))
ERROR:uvicorn.error:Exception in ASGI application
Traceback (most recent call last):
  File "/usr/local/lib/python3.8/dist-packages/uvicorn/protocols/http/h11_impl.py", line 373, in run_asgi
    result = await app(self.scope, self.receive, self.send)
  File "/usr/local/lib/python3.8/dist-packages/uvicorn/middleware/proxy_headers.py", line 75, in __call__
    return await self.app(scope, receive, send)
  File "/usr/local/lib/python3.8/dist-packages/fastapi/applications.py", line 208, in __call__
    await super().__call__(scope, receive, send)
  File "/usr/local/lib/python3.8/dist-packages/starlette/applications.py", line 112, in __call__
    await self.middleware_stack(scope, receive, send)
  File "/usr/local/lib/python3.8/dist-packages/starlette/middleware/errors.py", line 181, in __call__
    raise exc from None
  File "/usr/local/lib/python3.8/dist-packages/starlette/middleware/errors.py", line 159, in __call__
    await self.app(scope, receive, _send)
  File "/usr/local/lib/python3.8/dist-packages/starlette/middleware/cors.py", line 86, in __call__
    await self.simple_response(scope, receive, send, request_headers=headers)
  File "/usr/local/lib/python3.8/dist-packages/starlette/middleware/cors.py", line 142, in simple_response
    await self.app(scope, receive, send)
  File "/usr/local/lib/python3.8/dist-packages/starlette/exceptions.py", line 82, in __call__
    raise exc from None
  File "/usr/local/lib/python3.8/dist-packages/starlette/exceptions.py", line 71, in __call__
    await self.app(scope, receive, sender)
  File "/usr/local/lib/python3.8/dist-packages/starlette/routing.py", line 580, in __call__
    await route.handle(scope, receive, send)
  File "/usr/local/lib/python3.8/dist-packages/starlette/routing.py", line 241, in handle
    await self.app(scope, receive, send)
  File "/usr/local/lib/python3.8/dist-packages/starlette/routing.py", line 52, in app
    response = await func(request)
  File "/usr/local/lib/python3.8/dist-packages/fastapi/routing.py", line 226, in app
    raw_response = await run_endpoint_function(
  File "/usr/local/lib/python3.8/dist-packages/fastapi/routing.py", line 159, in run_endpoint_function
    return await dependant.call(**values)
  File "/root/rcs_api_server/app/routes/set_data.py", line 63, in set_command
    response=requests.post(url, json=command, headers=headers, timeout=2)
  File "/usr/local/lib/python3.8/dist-packages/requests/api.py", line 117, in post
    return request('post', url, data=data, json=json, **kwargs)
  File "/usr/local/lib/python3.8/dist-packages/requests/api.py", line 61, in request
    return session.request(method=method, url=url, **kwargs)
  File "/usr/local/lib/python3.8/dist-packages/requests/sessions.py", line 542, in request
    resp = self.send(prep, **send_kwargs)
  File "/usr/local/lib/python3.8/dist-packages/requests/sessions.py", line 655, in send
    r = adapter.send(request, **kwargs)
  File "/usr/local/lib/python3.8/dist-packages/requests/adapters.py", line 516, in send
    raise ConnectionError(e, request=request)
requests.exceptions.ConnectionError: HTTPConnectionPool(host='http', port=80): Max retries exceeded with url: //115.145.177.104:1827 (Caused by NewConnectionError('<urllib3.connection.HTTPConnection object at 0x7f5874cc3d00>: Failed to establish a new connection: [Errno -3] Temporary failure in name resolution'))
INFO:     115.145.177.104:34414 - "POST /set/set_command HTTP/1.1" 500 Internal Server Error
ERROR:    Exception in ASGI application
Traceback (most recent call last):
  File "/usr/local/lib/python3.8/dist-packages/uvicorn/protocols/http/h11_impl.py", line 373, in run_asgi
    result = await app(self.scope, self.receive, self.send)
  File "/usr/local/lib/python3.8/dist-packages/uvicorn/middleware/proxy_headers.py", line 75, in __call__
    return await self.app(scope, receive, send)
  File "/usr/local/lib/python3.8/dist-packages/fastapi/applications.py", line 208, in __call__
    await super().__call__(scope, receive, send)
  File "/usr/local/lib/python3.8/dist-packages/starlette/applications.py", line 112, in __call__
    await self.middleware_stack(scope, receive, send)
  File "/usr/local/lib/python3.8/dist-packages/starlette/middleware/errors.py", line 181, in __call__
    raise exc from None
  File "/usr/local/lib/python3.8/dist-packages/starlette/middleware/errors.py", line 159, in __call__
    await self.app(scope, receive, _send)
  File "/usr/local/lib/python3.8/dist-packages/starlette/middleware/cors.py", line 86, in __call__
    await self.simple_response(scope, receive, send, request_headers=headers)
  File "/usr/local/lib/python3.8/dist-packages/starlette/middleware/cors.py", line 142, in simple_response
    await self.app(scope, receive, send)
  File "/usr/local/lib/python3.8/dist-packages/starlette/exceptions.py", line 82, in __call__
    raise exc from None
  File "/usr/local/lib/python3.8/dist-packages/starlette/exceptions.py", line 71, in __call__
    await self.app(scope, receive, sender)
  File "/usr/local/lib/python3.8/dist-packages/starlette/routing.py", line 580, in __call__
    await route.handle(scope, receive, send)
  File "/usr/local/lib/python3.8/dist-packages/starlette/routing.py", line 241, in handle
    await self.app(scope, receive, send)
  File "/usr/local/lib/python3.8/dist-packages/starlette/routing.py", line 52, in app
    response = await func(request)
  File "/usr/local/lib/python3.8/dist-packages/fastapi/routing.py", line 226, in app
    raw_response = await run_endpoint_function(
  File "/usr/local/lib/python3.8/dist-packages/fastapi/routing.py", line 159, in run_endpoint_function
    return await dependant.call(**values)
  File "/root/rcs_api_server/app/routes/set_data.py", line 63, in set_command
    response=requests.post(url, json=command, headers=headers, timeout=2)
  File "/usr/local/lib/python3.8/dist-packages/requests/api.py", line 117, in post
    return request('post', url, data=data, json=json, **kwargs)
  File "/usr/local/lib/python3.8/dist-packages/requests/api.py", line 61, in request
    return session.request(method=method, url=url, **kwargs)
  File "/usr/local/lib/python3.8/dist-packages/requests/sessions.py", line 542, in request
    resp = self.send(prep, **send_kwargs)
  File "/usr/local/lib/python3.8/dist-packages/requests/sessions.py", line 655, in send
    r = adapter.send(request, **kwargs)
  File "/usr/local/lib/python3.8/dist-packages/requests/adapters.py", line 516, in send
    raise ConnectionError(e, request=request)
requests.exceptions.ConnectionError: HTTPConnectionPool(host='http', port=80): Max retries exceeded with url: //115.145.177.104:1827 (Caused by NewConnectionError('<urllib3.connection.HTTPConnection object at 0x7f5874cebca0>: Failed to establish a new connection: [Errno -3] Temporary failure in name resolution'))
ERROR:uvicorn.error:Exception in ASGI application
Traceback (most recent call last):
  File "/usr/local/lib/python3.8/dist-packages/uvicorn/protocols/http/h11_impl.py", line 373, in run_asgi
    result = await app(self.scope, self.receive, self.send)
  File "/usr/local/lib/python3.8/dist-packages/uvicorn/middleware/proxy_headers.py", line 75, in __call__
    return await self.app(scope, receive, send)
  File "/usr/local/lib/python3.8/dist-packages/fastapi/applications.py", line 208, in __call__
    await super().__call__(scope, receive, send)
  File "/usr/local/lib/python3.8/dist-packages/starlette/applications.py", line 112, in __call__
    await self.middleware_stack(scope, receive, send)
  File "/usr/local/lib/python3.8/dist-packages/starlette/middleware/errors.py", line 181, in __call__
    raise exc from None
  File "/usr/local/lib/python3.8/dist-packages/starlette/middleware/errors.py", line 159, in __call__
    await self.app(scope, receive, _send)
  File "/usr/local/lib/python3.8/dist-packages/starlette/middleware/cors.py", line 86, in __call__
    await self.simple_response(scope, receive, send, request_headers=headers)
  File "/usr/local/lib/python3.8/dist-packages/starlette/middleware/cors.py", line 142, in simple_response
    await self.app(scope, receive, send)
  File "/usr/local/lib/python3.8/dist-packages/starlette/exceptions.py", line 82, in __call__
    raise exc from None
  File "/usr/local/lib/python3.8/dist-packages/starlette/exceptions.py", line 71, in __call__
    await self.app(scope, receive, sender)
  File "/usr/local/lib/python3.8/dist-packages/starlette/routing.py", line 580, in __call__
    await route.handle(scope, receive, send)
  File "/usr/local/lib/python3.8/dist-packages/starlette/routing.py", line 241, in handle
    await self.app(scope, receive, send)
  File "/usr/local/lib/python3.8/dist-packages/starlette/routing.py", line 52, in app
    response = await func(request)
  File "/usr/local/lib/python3.8/dist-packages/fastapi/routing.py", line 226, in app
    raw_response = await run_endpoint_function(
  File "/usr/local/lib/python3.8/dist-packages/fastapi/routing.py", line 159, in run_endpoint_function
    return await dependant.call(**values)
  File "/root/rcs_api_server/app/routes/set_data.py", line 63, in set_command
    response=requests.post(url, json=command, headers=headers, timeout=2)
  File "/usr/local/lib/python3.8/dist-packages/requests/api.py", line 117, in post
    return request('post', url, data=data, json=json, **kwargs)
  File "/usr/local/lib/python3.8/dist-packages/requests/api.py", line 61, in request
    return session.request(method=method, url=url, **kwargs)
  File "/usr/local/lib/python3.8/dist-packages/requests/sessions.py", line 542, in request
    resp = self.send(prep, **send_kwargs)
  File "/usr/local/lib/python3.8/dist-packages/requests/sessions.py", line 655, in send
    r = adapter.send(request, **kwargs)
  File "/usr/local/lib/python3.8/dist-packages/requests/adapters.py", line 516, in send
    raise ConnectionError(e, request=request)
requests.exceptions.ConnectionError: HTTPConnectionPool(host='http', port=80): Max retries exceeded with url: //115.145.177.104:1827 (Caused by NewConnectionError('<urllib3.connection.HTTPConnection object at 0x7f5874cebca0>: Failed to establish a new connection: [Errno -3] Temporary failure in name resolution'))
INFO:     115.145.177.104:34486 - "POST /set/set_command HTTP/1.1" 500 Internal Server Error
ERROR:    Exception in ASGI application
Traceback (most recent call last):
  File "/usr/local/lib/python3.8/dist-packages/uvicorn/protocols/http/h11_impl.py", line 373, in run_asgi
    result = await app(self.scope, self.receive, self.send)
  File "/usr/local/lib/python3.8/dist-packages/uvicorn/middleware/proxy_headers.py", line 75, in __call__
    return await self.app(scope, receive, send)
  File "/usr/local/lib/python3.8/dist-packages/fastapi/applications.py", line 208, in __call__
    await super().__call__(scope, receive, send)
  File "/usr/local/lib/python3.8/dist-packages/starlette/applications.py", line 112, in __call__
    await self.middleware_stack(scope, receive, send)
  File "/usr/local/lib/python3.8/dist-packages/starlette/middleware/errors.py", line 181, in __call__
    raise exc from None
  File "/usr/local/lib/python3.8/dist-packages/starlette/middleware/errors.py", line 159, in __call__
    await self.app(scope, receive, _send)
  File "/usr/local/lib/python3.8/dist-packages/starlette/middleware/cors.py", line 86, in __call__
    await self.simple_response(scope, receive, send, request_headers=headers)
  File "/usr/local/lib/python3.8/dist-packages/starlette/middleware/cors.py", line 142, in simple_response
    await self.app(scope, receive, send)
  File "/usr/local/lib/python3.8/dist-packages/starlette/exceptions.py", line 82, in __call__
    raise exc from None
  File "/usr/local/lib/python3.8/dist-packages/starlette/exceptions.py", line 71, in __call__
    await self.app(scope, receive, sender)
  File "/usr/local/lib/python3.8/dist-packages/starlette/routing.py", line 580, in __call__
    await route.handle(scope, receive, send)
  File "/usr/local/lib/python3.8/dist-packages/starlette/routing.py", line 241, in handle
    await self.app(scope, receive, send)
  File "/usr/local/lib/python3.8/dist-packages/starlette/routing.py", line 52, in app
    response = await func(request)
  File "/usr/local/lib/python3.8/dist-packages/fastapi/routing.py", line 226, in app
    raw_response = await run_endpoint_function(
  File "/usr/local/lib/python3.8/dist-packages/fastapi/routing.py", line 159, in run_endpoint_function
    return await dependant.call(**values)
  File "/root/rcs_api_server/app/routes/set_data.py", line 63, in set_command
    response=requests.post(url, json=command, headers=headers, timeout=2)
  File "/usr/local/lib/python3.8/dist-packages/requests/api.py", line 117, in post
    return request('post', url, data=data, json=json, **kwargs)
  File "/usr/local/lib/python3.8/dist-packages/requests/api.py", line 61, in request
    return session.request(method=method, url=url, **kwargs)
  File "/usr/local/lib/python3.8/dist-packages/requests/sessions.py", line 542, in request
    resp = self.send(prep, **send_kwargs)
  File "/usr/local/lib/python3.8/dist-packages/requests/sessions.py", line 655, in send
    r = adapter.send(request, **kwargs)
  File "/usr/local/lib/python3.8/dist-packages/requests/adapters.py", line 516, in send
    raise ConnectionError(e, request=request)
requests.exceptions.ConnectionError: HTTPConnectionPool(host='http', port=80): Max retries exceeded with url: //115.145.177.104:1827 (Caused by NewConnectionError('<urllib3.connection.HTTPConnection object at 0x7f5873d5b130>: Failed to establish a new connection: [Errno -3] Temporary failure in name resolution'))
ERROR:uvicorn.error:Exception in ASGI application
Traceback (most recent call last):
  File "/usr/local/lib/python3.8/dist-packages/uvicorn/protocols/http/h11_impl.py", line 373, in run_asgi
    result = await app(self.scope, self.receive, self.send)
  File "/usr/local/lib/python3.8/dist-packages/uvicorn/middleware/proxy_headers.py", line 75, in __call__
    return await self.app(scope, receive, send)
  File "/usr/local/lib/python3.8/dist-packages/fastapi/applications.py", line 208, in __call__
    await super().__call__(scope, receive, send)
  File "/usr/local/lib/python3.8/dist-packages/starlette/applications.py", line 112, in __call__
    await self.middleware_stack(scope, receive, send)
  File "/usr/local/lib/python3.8/dist-packages/starlette/middleware/errors.py", line 181, in __call__
    raise exc from None
  File "/usr/local/lib/python3.8/dist-packages/starlette/middleware/errors.py", line 159, in __call__
    await self.app(scope, receive, _send)
  File "/usr/local/lib/python3.8/dist-packages/starlette/middleware/cors.py", line 86, in __call__
    await self.simple_response(scope, receive, send, request_headers=headers)
  File "/usr/local/lib/python3.8/dist-packages/starlette/middleware/cors.py", line 142, in simple_response
    await self.app(scope, receive, send)
  File "/usr/local/lib/python3.8/dist-packages/starlette/exceptions.py", line 82, in __call__
    raise exc from None
  File "/usr/local/lib/python3.8/dist-packages/starlette/exceptions.py", line 71, in __call__
    await self.app(scope, receive, sender)
  File "/usr/local/lib/python3.8/dist-packages/starlette/routing.py", line 580, in __call__
    await route.handle(scope, receive, send)
  File "/usr/local/lib/python3.8/dist-packages/starlette/routing.py", line 241, in handle
    await self.app(scope, receive, send)
  File "/usr/local/lib/python3.8/dist-packages/starlette/routing.py", line 52, in app
    response = await func(request)
  File "/usr/local/lib/python3.8/dist-packages/fastapi/routing.py", line 226, in app
    raw_response = await run_endpoint_function(
  File "/usr/local/lib/python3.8/dist-packages/fastapi/routing.py", line 159, in run_endpoint_function
    return await dependant.call(**values)
  File "/root/rcs_api_server/app/routes/set_data.py", line 63, in set_command
    response=requests.post(url, json=command, headers=headers, timeout=2)
  File "/usr/local/lib/python3.8/dist-packages/requests/api.py", line 117, in post
    return request('post', url, data=data, json=json, **kwargs)
  File "/usr/local/lib/python3.8/dist-packages/requests/api.py", line 61, in request
    return session.request(method=method, url=url, **kwargs)
  File "/usr/local/lib/python3.8/dist-packages/requests/sessions.py", line 542, in request
    resp = self.send(prep, **send_kwargs)
  File "/usr/local/lib/python3.8/dist-packages/requests/sessions.py", line 655, in send
    r = adapter.send(request, **kwargs)
  File "/usr/local/lib/python3.8/dist-packages/requests/adapters.py", line 516, in send
    raise ConnectionError(e, request=request)
requests.exceptions.ConnectionError: HTTPConnectionPool(host='http', port=80): Max retries exceeded with url: //115.145.177.104:1827 (Caused by NewConnectionError('<urllib3.connection.HTTPConnection object at 0x7f5873d5b130>: Failed to establish a new connection: [Errno -3] Temporary failure in name resolution'))
INFO:     115.145.177.104:35210 - "POST /set/set_command HTTP/1.1" 500 Internal Server Error
ERROR:    Exception in ASGI application
Traceback (most recent call last):
  File "/usr/local/lib/python3.8/dist-packages/uvicorn/protocols/http/h11_impl.py", line 373, in run_asgi
    result = await app(self.scope, self.receive, self.send)
  File "/usr/local/lib/python3.8/dist-packages/uvicorn/middleware/proxy_headers.py", line 75, in __call__
    return await self.app(scope, receive, send)
  File "/usr/local/lib/python3.8/dist-packages/fastapi/applications.py", line 208, in __call__
    await super().__call__(scope, receive, send)
  File "/usr/local/lib/python3.8/dist-packages/starlette/applications.py", line 112, in __call__
    await self.middleware_stack(scope, receive, send)
  File "/usr/local/lib/python3.8/dist-packages/starlette/middleware/errors.py", line 181, in __call__
    raise exc from None
  File "/usr/local/lib/python3.8/dist-packages/starlette/middleware/errors.py", line 159, in __call__
    await self.app(scope, receive, _send)
  File "/usr/local/lib/python3.8/dist-packages/starlette/middleware/cors.py", line 86, in __call__
    await self.simple_response(scope, receive, send, request_headers=headers)
  File "/usr/local/lib/python3.8/dist-packages/starlette/middleware/cors.py", line 142, in simple_response
    await self.app(scope, receive, send)
  File "/usr/local/lib/python3.8/dist-packages/starlette/exceptions.py", line 82, in __call__
    raise exc from None
  File "/usr/local/lib/python3.8/dist-packages/starlette/exceptions.py", line 71, in __call__
    await self.app(scope, receive, sender)
  File "/usr/local/lib/python3.8/dist-packages/starlette/routing.py", line 580, in __call__
    await route.handle(scope, receive, send)
  File "/usr/local/lib/python3.8/dist-packages/starlette/routing.py", line 241, in handle
    await self.app(scope, receive, send)
  File "/usr/local/lib/python3.8/dist-packages/starlette/routing.py", line 52, in app
    response = await func(request)
  File "/usr/local/lib/python3.8/dist-packages/fastapi/routing.py", line 226, in app
    raw_response = await run_endpoint_function(
  File "/usr/local/lib/python3.8/dist-packages/fastapi/routing.py", line 159, in run_endpoint_function
    return await dependant.call(**values)
  File "/root/rcs_api_server/app/routes/set_data.py", line 63, in set_command
    response=requests.post(url, json=command, headers=headers, timeout=2)
  File "/usr/local/lib/python3.8/dist-packages/requests/api.py", line 117, in post
    return request('post', url, data=data, json=json, **kwargs)
  File "/usr/local/lib/python3.8/dist-packages/requests/api.py", line 61, in request
    return session.request(method=method, url=url, **kwargs)
  File "/usr/local/lib/python3.8/dist-packages/requests/sessions.py", line 542, in request
    resp = self.send(prep, **send_kwargs)
  File "/usr/local/lib/python3.8/dist-packages/requests/sessions.py", line 655, in send
    r = adapter.send(request, **kwargs)
  File "/usr/local/lib/python3.8/dist-packages/requests/adapters.py", line 516, in send
    raise ConnectionError(e, request=request)
requests.exceptions.ConnectionError: HTTPConnectionPool(host='http', port=80): Max retries exceeded with url: //115.145.177.104:1827 (Caused by NewConnectionError('<urllib3.connection.HTTPConnection object at 0x7f5873d5b7c0>: Failed to establish a new connection: [Errno -3] Temporary failure in name resolution'))
ERROR:uvicorn.error:Exception in ASGI application
Traceback (most recent call last):
  File "/usr/local/lib/python3.8/dist-packages/uvicorn/protocols/http/h11_impl.py", line 373, in run_asgi
    result = await app(self.scope, self.receive, self.send)
  File "/usr/local/lib/python3.8/dist-packages/uvicorn/middleware/proxy_headers.py", line 75, in __call__
    return await self.app(scope, receive, send)
  File "/usr/local/lib/python3.8/dist-packages/fastapi/applications.py", line 208, in __call__
    await super().__call__(scope, receive, send)
  File "/usr/local/lib/python3.8/dist-packages/starlette/applications.py", line 112, in __call__
    await self.middleware_stack(scope, receive, send)
  File "/usr/local/lib/python3.8/dist-packages/starlette/middleware/errors.py", line 181, in __call__
    raise exc from None
  File "/usr/local/lib/python3.8/dist-packages/starlette/middleware/errors.py", line 159, in __call__
    await self.app(scope, receive, _send)
  File "/usr/local/lib/python3.8/dist-packages/starlette/middleware/cors.py", line 86, in __call__
    await self.simple_response(scope, receive, send, request_headers=headers)
  File "/usr/local/lib/python3.8/dist-packages/starlette/middleware/cors.py", line 142, in simple_response
    await self.app(scope, receive, send)
  File "/usr/local/lib/python3.8/dist-packages/starlette/exceptions.py", line 82, in __call__
    raise exc from None
  File "/usr/local/lib/python3.8/dist-packages/starlette/exceptions.py", line 71, in __call__
    await self.app(scope, receive, sender)
  File "/usr/local/lib/python3.8/dist-packages/starlette/routing.py", line 580, in __call__
    await route.handle(scope, receive, send)
  File "/usr/local/lib/python3.8/dist-packages/starlette/routing.py", line 241, in handle
    await self.app(scope, receive, send)
  File "/usr/local/lib/python3.8/dist-packages/starlette/routing.py", line 52, in app
    response = await func(request)
  File "/usr/local/lib/python3.8/dist-packages/fastapi/routing.py", line 226, in app
    raw_response = await run_endpoint_function(
  File "/usr/local/lib/python3.8/dist-packages/fastapi/routing.py", line 159, in run_endpoint_function
    return await dependant.call(**values)
  File "/root/rcs_api_server/app/routes/set_data.py", line 63, in set_command
    response=requests.post(url, json=command, headers=headers, timeout=2)
  File "/usr/local/lib/python3.8/dist-packages/requests/api.py", line 117, in post
    return request('post', url, data=data, json=json, **kwargs)
  File "/usr/local/lib/python3.8/dist-packages/requests/api.py", line 61, in request
    return session.request(method=method, url=url, **kwargs)
  File "/usr/local/lib/python3.8/dist-packages/requests/sessions.py", line 542, in request
    resp = self.send(prep, **send_kwargs)
  File "/usr/local/lib/python3.8/dist-packages/requests/sessions.py", line 655, in send
    r = adapter.send(request, **kwargs)
  File "/usr/local/lib/python3.8/dist-packages/requests/adapters.py", line 516, in send
    raise ConnectionError(e, request=request)
requests.exceptions.ConnectionError: HTTPConnectionPool(host='http', port=80): Max retries exceeded with url: //115.145.177.104:1827 (Caused by NewConnectionError('<urllib3.connection.HTTPConnection object at 0x7f5873d5b7c0>: Failed to establish a new connection: [Errno -3] Temporary failure in name resolution'))
INFO:     64.62.197.92:26408 - "GET / HTTP/1.1" 200 OK
WARNING:  Invalid HTTP request received.
Traceback (most recent call last):
  File "/usr/local/lib/python3.8/dist-packages/uvicorn/protocols/http/h11_impl.py", line 136, in handle_events
    event = self.conn.next_event()
  File "/usr/local/lib/python3.8/dist-packages/h11/_connection.py", line 443, in next_event
    exc._reraise_as_remote_protocol_error()
  File "/usr/local/lib/python3.8/dist-packages/h11/_util.py", line 76, in _reraise_as_remote_protocol_error
    raise self
  File "/usr/local/lib/python3.8/dist-packages/h11/_connection.py", line 425, in next_event
    event = self._extract_next_receive_event()
  File "/usr/local/lib/python3.8/dist-packages/h11/_connection.py", line 367, in _extract_next_receive_event
    event = self._reader(self._receive_buffer)
  File "/usr/local/lib/python3.8/dist-packages/h11/_readers.py", line 68, in maybe_read_from_IDLE_client
    raise LocalProtocolError("illegal request line")
h11._util.RemoteProtocolError: illegal request line
WARNING:uvicorn.error:Invalid HTTP request received.
Traceback (most recent call last):
  File "/usr/local/lib/python3.8/dist-packages/uvicorn/protocols/http/h11_impl.py", line 136, in handle_events
    event = self.conn.next_event()
  File "/usr/local/lib/python3.8/dist-packages/h11/_connection.py", line 443, in next_event
    exc._reraise_as_remote_protocol_error()
  File "/usr/local/lib/python3.8/dist-packages/h11/_util.py", line 76, in _reraise_as_remote_protocol_error
    raise self
  File "/usr/local/lib/python3.8/dist-packages/h11/_connection.py", line 425, in next_event
    event = self._extract_next_receive_event()
  File "/usr/local/lib/python3.8/dist-packages/h11/_connection.py", line 367, in _extract_next_receive_event
    event = self._reader(self._receive_buffer)
  File "/usr/local/lib/python3.8/dist-packages/h11/_readers.py", line 68, in maybe_read_from_IDLE_client
    raise LocalProtocolError("illegal request line")
h11._util.RemoteProtocolError: illegal request line
WARNING:  Invalid HTTP request received.
Traceback (most recent call last):
  File "/usr/local/lib/python3.8/dist-packages/uvicorn/protocols/http/h11_impl.py", line 136, in handle_events
    event = self.conn.next_event()
  File "/usr/local/lib/python3.8/dist-packages/h11/_connection.py", line 443, in next_event
    exc._reraise_as_remote_protocol_error()
  File "/usr/local/lib/python3.8/dist-packages/h11/_util.py", line 76, in _reraise_as_remote_protocol_error
    raise self
  File "/usr/local/lib/python3.8/dist-packages/h11/_connection.py", line 425, in next_event
    event = self._extract_next_receive_event()
  File "/usr/local/lib/python3.8/dist-packages/h11/_connection.py", line 367, in _extract_next_receive_event
    event = self._reader(self._receive_buffer)
  File "/usr/local/lib/python3.8/dist-packages/h11/_readers.py", line 68, in maybe_read_from_IDLE_client
    raise LocalProtocolError("illegal request line")
h11._util.RemoteProtocolError: illegal request line
WARNING:uvicorn.error:Invalid HTTP request received.
Traceback (most recent call last):
  File "/usr/local/lib/python3.8/dist-packages/uvicorn/protocols/http/h11_impl.py", line 136, in handle_events
    event = self.conn.next_event()
  File "/usr/local/lib/python3.8/dist-packages/h11/_connection.py", line 443, in next_event
    exc._reraise_as_remote_protocol_error()
  File "/usr/local/lib/python3.8/dist-packages/h11/_util.py", line 76, in _reraise_as_remote_protocol_error
    raise self
  File "/usr/local/lib/python3.8/dist-packages/h11/_connection.py", line 425, in next_event
    event = self._extract_next_receive_event()
  File "/usr/local/lib/python3.8/dist-packages/h11/_connection.py", line 367, in _extract_next_receive_event
    event = self._reader(self._receive_buffer)
  File "/usr/local/lib/python3.8/dist-packages/h11/_readers.py", line 68, in maybe_read_from_IDLE_client
    raise LocalProtocolError("illegal request line")
h11._util.RemoteProtocolError: illegal request line
INFO:     89.248.165.52:36976 - "CONNECT hotmail-com.olc.protection.outlook.com%3A25 HTTP/1.1" 404 Not Found
INFO:     66.240.192.138:35880 - "GET / HTTP/1.1" 200 OK
INFO:     66.240.192.138:36418 - "GET /favicon.ico HTTP/1.1" 404 Not Found
WARNING:  Invalid HTTP request received.
Traceback (most recent call last):
  File "/usr/local/lib/python3.8/dist-packages/uvicorn/protocols/http/h11_impl.py", line 136, in handle_events
    event = self.conn.next_event()
  File "/usr/local/lib/python3.8/dist-packages/h11/_connection.py", line 443, in next_event
    exc._reraise_as_remote_protocol_error()
  File "/usr/local/lib/python3.8/dist-packages/h11/_util.py", line 76, in _reraise_as_remote_protocol_error
    raise self
  File "/usr/local/lib/python3.8/dist-packages/h11/_connection.py", line 425, in next_event
    event = self._extract_next_receive_event()
  File "/usr/local/lib/python3.8/dist-packages/h11/_connection.py", line 367, in _extract_next_receive_event
    event = self._reader(self._receive_buffer)
  File "/usr/local/lib/python3.8/dist-packages/h11/_readers.py", line 68, in maybe_read_from_IDLE_client
    raise LocalProtocolError("illegal request line")
h11._util.RemoteProtocolError: illegal request line
WARNING:uvicorn.error:Invalid HTTP request received.
Traceback (most recent call last):
  File "/usr/local/lib/python3.8/dist-packages/uvicorn/protocols/http/h11_impl.py", line 136, in handle_events
    event = self.conn.next_event()
  File "/usr/local/lib/python3.8/dist-packages/h11/_connection.py", line 443, in next_event
    exc._reraise_as_remote_protocol_error()
  File "/usr/local/lib/python3.8/dist-packages/h11/_util.py", line 76, in _reraise_as_remote_protocol_error
    raise self
  File "/usr/local/lib/python3.8/dist-packages/h11/_connection.py", line 425, in next_event
    event = self._extract_next_receive_event()
  File "/usr/local/lib/python3.8/dist-packages/h11/_connection.py", line 367, in _extract_next_receive_event
    event = self._reader(self._receive_buffer)
  File "/usr/local/lib/python3.8/dist-packages/h11/_readers.py", line 68, in maybe_read_from_IDLE_client
    raise LocalProtocolError("illegal request line")
h11._util.RemoteProtocolError: illegal request line
WARNING:  Invalid HTTP request received.
Traceback (most recent call last):
  File "/usr/local/lib/python3.8/dist-packages/uvicorn/protocols/http/h11_impl.py", line 136, in handle_events
    event = self.conn.next_event()
  File "/usr/local/lib/python3.8/dist-packages/h11/_connection.py", line 443, in next_event
    exc._reraise_as_remote_protocol_error()
  File "/usr/local/lib/python3.8/dist-packages/h11/_util.py", line 76, in _reraise_as_remote_protocol_error
    raise self
  File "/usr/local/lib/python3.8/dist-packages/h11/_connection.py", line 425, in next_event
    event = self._extract_next_receive_event()
  File "/usr/local/lib/python3.8/dist-packages/h11/_connection.py", line 367, in _extract_next_receive_event
    event = self._reader(self._receive_buffer)
  File "/usr/local/lib/python3.8/dist-packages/h11/_readers.py", line 68, in maybe_read_from_IDLE_client
    raise LocalProtocolError("illegal request line")
h11._util.RemoteProtocolError: illegal request line
WARNING:uvicorn.error:Invalid HTTP request received.
Traceback (most recent call last):
  File "/usr/local/lib/python3.8/dist-packages/uvicorn/protocols/http/h11_impl.py", line 136, in handle_events
    event = self.conn.next_event()
  File "/usr/local/lib/python3.8/dist-packages/h11/_connection.py", line 443, in next_event
    exc._reraise_as_remote_protocol_error()
  File "/usr/local/lib/python3.8/dist-packages/h11/_util.py", line 76, in _reraise_as_remote_protocol_error
    raise self
  File "/usr/local/lib/python3.8/dist-packages/h11/_connection.py", line 425, in next_event
    event = self._extract_next_receive_event()
  File "/usr/local/lib/python3.8/dist-packages/h11/_connection.py", line 367, in _extract_next_receive_event
    event = self._reader(self._receive_buffer)
  File "/usr/local/lib/python3.8/dist-packages/h11/_readers.py", line 68, in maybe_read_from_IDLE_client
    raise LocalProtocolError("illegal request line")
h11._util.RemoteProtocolError: illegal request line
WARNING:  Invalid HTTP request received.
Traceback (most recent call last):
  File "/usr/local/lib/python3.8/dist-packages/uvicorn/protocols/http/h11_impl.py", line 136, in handle_events
    event = self.conn.next_event()
  File "/usr/local/lib/python3.8/dist-packages/h11/_connection.py", line 443, in next_event
    exc._reraise_as_remote_protocol_error()
  File "/usr/local/lib/python3.8/dist-packages/h11/_util.py", line 76, in _reraise_as_remote_protocol_error
    raise self
  File "/usr/local/lib/python3.8/dist-packages/h11/_connection.py", line 425, in next_event
    event = self._extract_next_receive_event()
  File "/usr/local/lib/python3.8/dist-packages/h11/_connection.py", line 367, in _extract_next_receive_event
    event = self._reader(self._receive_buffer)
  File "/usr/local/lib/python3.8/dist-packages/h11/_readers.py", line 68, in maybe_read_from_IDLE_client
    raise LocalProtocolError("illegal request line")
h11._util.RemoteProtocolError: illegal request line
WARNING:uvicorn.error:Invalid HTTP request received.
Traceback (most recent call last):
  File "/usr/local/lib/python3.8/dist-packages/uvicorn/protocols/http/h11_impl.py", line 136, in handle_events
    event = self.conn.next_event()
  File "/usr/local/lib/python3.8/dist-packages/h11/_connection.py", line 443, in next_event
    exc._reraise_as_remote_protocol_error()
  File "/usr/local/lib/python3.8/dist-packages/h11/_util.py", line 76, in _reraise_as_remote_protocol_error
    raise self
  File "/usr/local/lib/python3.8/dist-packages/h11/_connection.py", line 425, in next_event
    event = self._extract_next_receive_event()
  File "/usr/local/lib/python3.8/dist-packages/h11/_connection.py", line 367, in _extract_next_receive_event
    event = self._reader(self._receive_buffer)
  File "/usr/local/lib/python3.8/dist-packages/h11/_readers.py", line 68, in maybe_read_from_IDLE_client
    raise LocalProtocolError("illegal request line")
h11._util.RemoteProtocolError: illegal request line
INFO:     89.248.165.52:54882 - "CONNECT 85.206.160.115%3A80 HTTP/1.1" 404 Not Found
INFO:     167.94.138.59:53158 - "GET / HTTP/1.1" 200 OK
INFO:     167.94.138.59:49974 - "GET / HTTP/1.1" 200 OK
WARNING:  Invalid HTTP request received.
Traceback (most recent call last):
  File "/usr/local/lib/python3.8/dist-packages/uvicorn/protocols/http/h11_impl.py", line 136, in handle_events
    event = self.conn.next_event()
  File "/usr/local/lib/python3.8/dist-packages/h11/_connection.py", line 443, in next_event
    exc._reraise_as_remote_protocol_error()
  File "/usr/local/lib/python3.8/dist-packages/h11/_util.py", line 76, in _reraise_as_remote_protocol_error
    raise self
  File "/usr/local/lib/python3.8/dist-packages/h11/_connection.py", line 425, in next_event
    event = self._extract_next_receive_event()
  File "/usr/local/lib/python3.8/dist-packages/h11/_connection.py", line 367, in _extract_next_receive_event
    event = self._reader(self._receive_buffer)
  File "/usr/local/lib/python3.8/dist-packages/h11/_readers.py", line 68, in maybe_read_from_IDLE_client
    raise LocalProtocolError("illegal request line")
h11._util.RemoteProtocolError: illegal request line
WARNING:uvicorn.error:Invalid HTTP request received.
Traceback (most recent call last):
  File "/usr/local/lib/python3.8/dist-packages/uvicorn/protocols/http/h11_impl.py", line 136, in handle_events
    event = self.conn.next_event()
  File "/usr/local/lib/python3.8/dist-packages/h11/_connection.py", line 443, in next_event
    exc._reraise_as_remote_protocol_error()
  File "/usr/local/lib/python3.8/dist-packages/h11/_util.py", line 76, in _reraise_as_remote_protocol_error
    raise self
  File "/usr/local/lib/python3.8/dist-packages/h11/_connection.py", line 425, in next_event
    event = self._extract_next_receive_event()
  File "/usr/local/lib/python3.8/dist-packages/h11/_connection.py", line 367, in _extract_next_receive_event
    event = self._reader(self._receive_buffer)
  File "/usr/local/lib/python3.8/dist-packages/h11/_readers.py", line 68, in maybe_read_from_IDLE_client
    raise LocalProtocolError("illegal request line")
h11._util.RemoteProtocolError: illegal request line
WARNING:  Invalid HTTP request received.
Traceback (most recent call last):
  File "/usr/local/lib/python3.8/dist-packages/uvicorn/protocols/http/h11_impl.py", line 136, in handle_events
    event = self.conn.next_event()
  File "/usr/local/lib/python3.8/dist-packages/h11/_connection.py", line 443, in next_event
    exc._reraise_as_remote_protocol_error()
  File "/usr/local/lib/python3.8/dist-packages/h11/_util.py", line 76, in _reraise_as_remote_protocol_error
    raise self
  File "/usr/local/lib/python3.8/dist-packages/h11/_connection.py", line 425, in next_event
    event = self._extract_next_receive_event()
  File "/usr/local/lib/python3.8/dist-packages/h11/_connection.py", line 367, in _extract_next_receive_event
    event = self._reader(self._receive_buffer)
  File "/usr/local/lib/python3.8/dist-packages/h11/_readers.py", line 68, in maybe_read_from_IDLE_client
    raise LocalProtocolError("illegal request line")
h11._util.RemoteProtocolError: illegal request line
WARNING:uvicorn.error:Invalid HTTP request received.
Traceback (most recent call last):
  File "/usr/local/lib/python3.8/dist-packages/uvicorn/protocols/http/h11_impl.py", line 136, in handle_events
    event = self.conn.next_event()
  File "/usr/local/lib/python3.8/dist-packages/h11/_connection.py", line 443, in next_event
    exc._reraise_as_remote_protocol_error()
  File "/usr/local/lib/python3.8/dist-packages/h11/_util.py", line 76, in _reraise_as_remote_protocol_error
    raise self
  File "/usr/local/lib/python3.8/dist-packages/h11/_connection.py", line 425, in next_event
    event = self._extract_next_receive_event()
  File "/usr/local/lib/python3.8/dist-packages/h11/_connection.py", line 367, in _extract_next_receive_event
    event = self._reader(self._receive_buffer)
  File "/usr/local/lib/python3.8/dist-packages/h11/_readers.py", line 68, in maybe_read_from_IDLE_client
    raise LocalProtocolError("illegal request line")
h11._util.RemoteProtocolError: illegal request line
WARNING:  Invalid HTTP request received.
Traceback (most recent call last):
  File "/usr/local/lib/python3.8/dist-packages/uvicorn/protocols/http/h11_impl.py", line 136, in handle_events
    event = self.conn.next_event()
  File "/usr/local/lib/python3.8/dist-packages/h11/_connection.py", line 443, in next_event
    exc._reraise_as_remote_protocol_error()
  File "/usr/local/lib/python3.8/dist-packages/h11/_util.py", line 76, in _reraise_as_remote_protocol_error
    raise self
  File "/usr/local/lib/python3.8/dist-packages/h11/_connection.py", line 425, in next_event
    event = self._extract_next_receive_event()
  File "/usr/local/lib/python3.8/dist-packages/h11/_connection.py", line 367, in _extract_next_receive_event
    event = self._reader(self._receive_buffer)
  File "/usr/local/lib/python3.8/dist-packages/h11/_readers.py", line 71, in maybe_read_from_IDLE_client
    raise LocalProtocolError("no request line received")
h11._util.RemoteProtocolError: no request line received
WARNING:uvicorn.error:Invalid HTTP request received.
Traceback (most recent call last):
  File "/usr/local/lib/python3.8/dist-packages/uvicorn/protocols/http/h11_impl.py", line 136, in handle_events
    event = self.conn.next_event()
  File "/usr/local/lib/python3.8/dist-packages/h11/_connection.py", line 443, in next_event
    exc._reraise_as_remote_protocol_error()
  File "/usr/local/lib/python3.8/dist-packages/h11/_util.py", line 76, in _reraise_as_remote_protocol_error
    raise self
  File "/usr/local/lib/python3.8/dist-packages/h11/_connection.py", line 425, in next_event
    event = self._extract_next_receive_event()
  File "/usr/local/lib/python3.8/dist-packages/h11/_connection.py", line 367, in _extract_next_receive_event
    event = self._reader(self._receive_buffer)
  File "/usr/local/lib/python3.8/dist-packages/h11/_readers.py", line 71, in maybe_read_from_IDLE_client
    raise LocalProtocolError("no request line received")
h11._util.RemoteProtocolError: no request line received
INFO:     137.220.233.52:49916 - "GET / HTTP/1.1" 200 OK
INFO:     137.220.233.52:51164 - "GET /favicon.ico HTTP/1.1" 404 Not Found
INFO:     137.220.233.52:51188 - "GET /robots.txt HTTP/1.1" 404 Not Found
INFO:     137.220.233.52:51220 - "GET /sitemap.xml HTTP/1.1" 404 Not Found
WARNING:  Invalid HTTP request received.
Traceback (most recent call last):
  File "/usr/local/lib/python3.8/dist-packages/uvicorn/protocols/http/h11_impl.py", line 136, in handle_events
    event = self.conn.next_event()
  File "/usr/local/lib/python3.8/dist-packages/h11/_connection.py", line 443, in next_event
    exc._reraise_as_remote_protocol_error()
  File "/usr/local/lib/python3.8/dist-packages/h11/_util.py", line 76, in _reraise_as_remote_protocol_error
    raise self
  File "/usr/local/lib/python3.8/dist-packages/h11/_connection.py", line 425, in next_event
    event = self._extract_next_receive_event()
  File "/usr/local/lib/python3.8/dist-packages/h11/_connection.py", line 367, in _extract_next_receive_event
    event = self._reader(self._receive_buffer)
  File "/usr/local/lib/python3.8/dist-packages/h11/_readers.py", line 68, in maybe_read_from_IDLE_client
    raise LocalProtocolError("illegal request line")
h11._util.RemoteProtocolError: illegal request line
WARNING:uvicorn.error:Invalid HTTP request received.
Traceback (most recent call last):
  File "/usr/local/lib/python3.8/dist-packages/uvicorn/protocols/http/h11_impl.py", line 136, in handle_events
    event = self.conn.next_event()
  File "/usr/local/lib/python3.8/dist-packages/h11/_connection.py", line 443, in next_event
    exc._reraise_as_remote_protocol_error()
  File "/usr/local/lib/python3.8/dist-packages/h11/_util.py", line 76, in _reraise_as_remote_protocol_error
    raise self
  File "/usr/local/lib/python3.8/dist-packages/h11/_connection.py", line 425, in next_event
    event = self._extract_next_receive_event()
  File "/usr/local/lib/python3.8/dist-packages/h11/_connection.py", line 367, in _extract_next_receive_event
    event = self._reader(self._receive_buffer)
  File "/usr/local/lib/python3.8/dist-packages/h11/_readers.py", line 68, in maybe_read_from_IDLE_client
    raise LocalProtocolError("illegal request line")
h11._util.RemoteProtocolError: illegal request line
INFO:     185.216.140.186:38404 - "GET http%3A//www.baidu.com/cache/global/img/gs.gif HTTP/1.1" 404 Not Found
WARNING:  Invalid HTTP request received.
Traceback (most recent call last):
  File "/usr/local/lib/python3.8/dist-packages/uvicorn/protocols/http/h11_impl.py", line 136, in handle_events
    event = self.conn.next_event()
  File "/usr/local/lib/python3.8/dist-packages/h11/_connection.py", line 443, in next_event
    exc._reraise_as_remote_protocol_error()
  File "/usr/local/lib/python3.8/dist-packages/h11/_util.py", line 76, in _reraise_as_remote_protocol_error
    raise self
  File "/usr/local/lib/python3.8/dist-packages/h11/_connection.py", line 425, in next_event
    event = self._extract_next_receive_event()
  File "/usr/local/lib/python3.8/dist-packages/h11/_connection.py", line 367, in _extract_next_receive_event
    event = self._reader(self._receive_buffer)
  File "/usr/local/lib/python3.8/dist-packages/h11/_readers.py", line 68, in maybe_read_from_IDLE_client
    raise LocalProtocolError("illegal request line")
h11._util.RemoteProtocolError: illegal request line
WARNING:uvicorn.error:Invalid HTTP request received.
Traceback (most recent call last):
  File "/usr/local/lib/python3.8/dist-packages/uvicorn/protocols/http/h11_impl.py", line 136, in handle_events
    event = self.conn.next_event()
  File "/usr/local/lib/python3.8/dist-packages/h11/_connection.py", line 443, in next_event
    exc._reraise_as_remote_protocol_error()
  File "/usr/local/lib/python3.8/dist-packages/h11/_util.py", line 76, in _reraise_as_remote_protocol_error
    raise self
  File "/usr/local/lib/python3.8/dist-packages/h11/_connection.py", line 425, in next_event
    event = self._extract_next_receive_event()
  File "/usr/local/lib/python3.8/dist-packages/h11/_connection.py", line 367, in _extract_next_receive_event
    event = self._reader(self._receive_buffer)
  File "/usr/local/lib/python3.8/dist-packages/h11/_readers.py", line 68, in maybe_read_from_IDLE_client
    raise LocalProtocolError("illegal request line")
h11._util.RemoteProtocolError: illegal request line
INFO:     103.203.57.20:52968 - "GET / HTTP/1.1" 200 OK
INFO:     216.218.206.67:41614 - "GET / HTTP/1.1" 200 OK
INFO:     157.245.52.232:33732 - "GET / HTTP/1.1" 200 OK
INFO:     167.94.138.116:60170 - "GET / HTTP/1.1" 200 OK
WARNING:  Invalid HTTP request received.
Traceback (most recent call last):
  File "/usr/local/lib/python3.8/dist-packages/uvicorn/protocols/http/h11_impl.py", line 136, in handle_events
    event = self.conn.next_event()
  File "/usr/local/lib/python3.8/dist-packages/h11/_connection.py", line 443, in next_event
    exc._reraise_as_remote_protocol_error()
  File "/usr/local/lib/python3.8/dist-packages/h11/_util.py", line 76, in _reraise_as_remote_protocol_error
    raise self
  File "/usr/local/lib/python3.8/dist-packages/h11/_connection.py", line 425, in next_event
    event = self._extract_next_receive_event()
  File "/usr/local/lib/python3.8/dist-packages/h11/_connection.py", line 367, in _extract_next_receive_event
    event = self._reader(self._receive_buffer)
  File "/usr/local/lib/python3.8/dist-packages/h11/_readers.py", line 68, in maybe_read_from_IDLE_client
    raise LocalProtocolError("illegal request line")
h11._util.RemoteProtocolError: illegal request line
WARNING:uvicorn.error:Invalid HTTP request received.
Traceback (most recent call last):
  File "/usr/local/lib/python3.8/dist-packages/uvicorn/protocols/http/h11_impl.py", line 136, in handle_events
    event = self.conn.next_event()
  File "/usr/local/lib/python3.8/dist-packages/h11/_connection.py", line 443, in next_event
    exc._reraise_as_remote_protocol_error()
  File "/usr/local/lib/python3.8/dist-packages/h11/_util.py", line 76, in _reraise_as_remote_protocol_error
    raise self
  File "/usr/local/lib/python3.8/dist-packages/h11/_connection.py", line 425, in next_event
    event = self._extract_next_receive_event()
  File "/usr/local/lib/python3.8/dist-packages/h11/_connection.py", line 367, in _extract_next_receive_event
    event = self._reader(self._receive_buffer)
  File "/usr/local/lib/python3.8/dist-packages/h11/_readers.py", line 68, in maybe_read_from_IDLE_client
    raise LocalProtocolError("illegal request line")
h11._util.RemoteProtocolError: illegal request line
INFO:     115.145.177.104:40464 - "GET / HTTP/1.1" 200 OK
INFO:     115.145.177.104:40464 - "GET /favicon.ico HTTP/1.1" 404 Not Found
INFO:     115.145.177.104:40464 - "GET /docs HTTP/1.1" 200 OK
INFO:     115.145.177.104:40464 - "GET /openapi.json HTTP/1.1" 200 OK
INFO:     115.145.177.104:44608 - "POST /set/set_command HTTP/1.1" 200 OK
INFO:     115.145.177.104:45380 - "POST /set/set_command HTTP/1.1" 200 OK
INFO:     115.145.177.104:48716 - "POST /set/set_command HTTP/1.1" 200 OK
INFO:     115.145.177.104:53326 - "POST /set/set_command HTTP/1.1" 200 OK
INFO:     115.145.177.104:54378 - "POST /set/set_command HTTP/1.1" 200 OK
INFO:     115.145.177.104:55412 - "POST /set/set_command HTTP/1.1" 500 Internal Server Error
ERROR:    Exception in ASGI application
Traceback (most recent call last):
  File "/usr/local/lib/python3.8/dist-packages/uvicorn/protocols/http/h11_impl.py", line 373, in run_asgi
    result = await app(self.scope, self.receive, self.send)
  File "/usr/local/lib/python3.8/dist-packages/uvicorn/middleware/proxy_headers.py", line 75, in __call__
    return await self.app(scope, receive, send)
  File "/usr/local/lib/python3.8/dist-packages/fastapi/applications.py", line 208, in __call__
    await super().__call__(scope, receive, send)
  File "/usr/local/lib/python3.8/dist-packages/starlette/applications.py", line 112, in __call__
    await self.middleware_stack(scope, receive, send)
  File "/usr/local/lib/python3.8/dist-packages/starlette/middleware/errors.py", line 181, in __call__
    raise exc from None
  File "/usr/local/lib/python3.8/dist-packages/starlette/middleware/errors.py", line 159, in __call__
    await self.app(scope, receive, _send)
  File "/usr/local/lib/python3.8/dist-packages/starlette/middleware/cors.py", line 86, in __call__
    await self.simple_response(scope, receive, send, request_headers=headers)
  File "/usr/local/lib/python3.8/dist-packages/starlette/middleware/cors.py", line 142, in simple_response
    await self.app(scope, receive, send)
  File "/usr/local/lib/python3.8/dist-packages/starlette/exceptions.py", line 82, in __call__
    raise exc from None
  File "/usr/local/lib/python3.8/dist-packages/starlette/exceptions.py", line 71, in __call__
    await self.app(scope, receive, sender)
  File "/usr/local/lib/python3.8/dist-packages/starlette/routing.py", line 580, in __call__
    await route.handle(scope, receive, send)
  File "/usr/local/lib/python3.8/dist-packages/starlette/routing.py", line 241, in handle
    await self.app(scope, receive, send)
  File "/usr/local/lib/python3.8/dist-packages/starlette/routing.py", line 52, in app
    response = await func(request)
  File "/usr/local/lib/python3.8/dist-packages/fastapi/routing.py", line 226, in app
    raw_response = await run_endpoint_function(
  File "/usr/local/lib/python3.8/dist-packages/fastapi/routing.py", line 159, in run_endpoint_function
    return await dependant.call(**values)
  File "/root/rcs_api_server/app/routes/set_data.py", line 63, in set_command
    response=requests.post(url, json=command, headers=headers, timeout=2)
  File "/usr/local/lib/python3.8/dist-packages/requests/api.py", line 117, in post
    return request('post', url, data=data, json=json, **kwargs)
  File "/usr/local/lib/python3.8/dist-packages/requests/api.py", line 61, in request
    return session.request(method=method, url=url, **kwargs)
  File "/usr/local/lib/python3.8/dist-packages/requests/sessions.py", line 542, in request
    resp = self.send(prep, **send_kwargs)
  File "/usr/local/lib/python3.8/dist-packages/requests/sessions.py", line 655, in send
    r = adapter.send(request, **kwargs)
  File "/usr/local/lib/python3.8/dist-packages/requests/adapters.py", line 529, in send
    raise ReadTimeout(e, request=request)
requests.exceptions.ReadTimeout: HTTPConnectionPool(host='115.145.177.104', port=1827): Read timed out. (read timeout=2)
ERROR:uvicorn.error:Exception in ASGI application
Traceback (most recent call last):
  File "/usr/local/lib/python3.8/dist-packages/uvicorn/protocols/http/h11_impl.py", line 373, in run_asgi
    result = await app(self.scope, self.receive, self.send)
  File "/usr/local/lib/python3.8/dist-packages/uvicorn/middleware/proxy_headers.py", line 75, in __call__
    return await self.app(scope, receive, send)
  File "/usr/local/lib/python3.8/dist-packages/fastapi/applications.py", line 208, in __call__
    await super().__call__(scope, receive, send)
  File "/usr/local/lib/python3.8/dist-packages/starlette/applications.py", line 112, in __call__
    await self.middleware_stack(scope, receive, send)
  File "/usr/local/lib/python3.8/dist-packages/starlette/middleware/errors.py", line 181, in __call__
    raise exc from None
  File "/usr/local/lib/python3.8/dist-packages/starlette/middleware/errors.py", line 159, in __call__
    await self.app(scope, receive, _send)
  File "/usr/local/lib/python3.8/dist-packages/starlette/middleware/cors.py", line 86, in __call__
    await self.simple_response(scope, receive, send, request_headers=headers)
  File "/usr/local/lib/python3.8/dist-packages/starlette/middleware/cors.py", line 142, in simple_response
    await self.app(scope, receive, send)
  File "/usr/local/lib/python3.8/dist-packages/starlette/exceptions.py", line 82, in __call__
    raise exc from None
  File "/usr/local/lib/python3.8/dist-packages/starlette/exceptions.py", line 71, in __call__
    await self.app(scope, receive, sender)
  File "/usr/local/lib/python3.8/dist-packages/starlette/routing.py", line 580, in __call__
    await route.handle(scope, receive, send)
  File "/usr/local/lib/python3.8/dist-packages/starlette/routing.py", line 241, in handle
    await self.app(scope, receive, send)
  File "/usr/local/lib/python3.8/dist-packages/starlette/routing.py", line 52, in app
    response = await func(request)
  File "/usr/local/lib/python3.8/dist-packages/fastapi/routing.py", line 226, in app
    raw_response = await run_endpoint_function(
  File "/usr/local/lib/python3.8/dist-packages/fastapi/routing.py", line 159, in run_endpoint_function
    return await dependant.call(**values)
  File "/root/rcs_api_server/app/routes/set_data.py", line 63, in set_command
    response=requests.post(url, json=command, headers=headers, timeout=2)
  File "/usr/local/lib/python3.8/dist-packages/requests/api.py", line 117, in post
    return request('post', url, data=data, json=json, **kwargs)
  File "/usr/local/lib/python3.8/dist-packages/requests/api.py", line 61, in request
    return session.request(method=method, url=url, **kwargs)
  File "/usr/local/lib/python3.8/dist-packages/requests/sessions.py", line 542, in request
    resp = self.send(prep, **send_kwargs)
  File "/usr/local/lib/python3.8/dist-packages/requests/sessions.py", line 655, in send
    r = adapter.send(request, **kwargs)
  File "/usr/local/lib/python3.8/dist-packages/requests/adapters.py", line 529, in send
    raise ReadTimeout(e, request=request)
requests.exceptions.ReadTimeout: HTTPConnectionPool(host='115.145.177.104', port=1827): Read timed out. (read timeout=2)
INFO:     115.145.177.104:56734 - "POST /set/set_command HTTP/1.1" 200 OK
INFO:     115.145.177.104:57240 - "POST /set/set_command HTTP/1.1" 500 Internal Server Error
ERROR:    Exception in ASGI application
Traceback (most recent call last):
  File "/usr/local/lib/python3.8/dist-packages/uvicorn/protocols/http/h11_impl.py", line 373, in run_asgi
    result = await app(self.scope, self.receive, self.send)
  File "/usr/local/lib/python3.8/dist-packages/uvicorn/middleware/proxy_headers.py", line 75, in __call__
    return await self.app(scope, receive, send)
  File "/usr/local/lib/python3.8/dist-packages/fastapi/applications.py", line 208, in __call__
    await super().__call__(scope, receive, send)
  File "/usr/local/lib/python3.8/dist-packages/starlette/applications.py", line 112, in __call__
    await self.middleware_stack(scope, receive, send)
  File "/usr/local/lib/python3.8/dist-packages/starlette/middleware/errors.py", line 181, in __call__
    raise exc from None
  File "/usr/local/lib/python3.8/dist-packages/starlette/middleware/errors.py", line 159, in __call__
    await self.app(scope, receive, _send)
  File "/usr/local/lib/python3.8/dist-packages/starlette/middleware/cors.py", line 86, in __call__
    await self.simple_response(scope, receive, send, request_headers=headers)
  File "/usr/local/lib/python3.8/dist-packages/starlette/middleware/cors.py", line 142, in simple_response
    await self.app(scope, receive, send)
  File "/usr/local/lib/python3.8/dist-packages/starlette/exceptions.py", line 82, in __call__
    raise exc from None
  File "/usr/local/lib/python3.8/dist-packages/starlette/exceptions.py", line 71, in __call__
    await self.app(scope, receive, sender)
  File "/usr/local/lib/python3.8/dist-packages/starlette/routing.py", line 580, in __call__
    await route.handle(scope, receive, send)
  File "/usr/local/lib/python3.8/dist-packages/starlette/routing.py", line 241, in handle
    await self.app(scope, receive, send)
  File "/usr/local/lib/python3.8/dist-packages/starlette/routing.py", line 52, in app
    response = await func(request)
  File "/usr/local/lib/python3.8/dist-packages/fastapi/routing.py", line 226, in app
    raw_response = await run_endpoint_function(
  File "/usr/local/lib/python3.8/dist-packages/fastapi/routing.py", line 159, in run_endpoint_function
    return await dependant.call(**values)
  File "/root/rcs_api_server/app/routes/set_data.py", line 63, in set_command
    response=requests.post(url, json=command, headers=headers, timeout=2)
  File "/usr/local/lib/python3.8/dist-packages/requests/api.py", line 117, in post
    return request('post', url, data=data, json=json, **kwargs)
  File "/usr/local/lib/python3.8/dist-packages/requests/api.py", line 61, in request
    return session.request(method=method, url=url, **kwargs)
  File "/usr/local/lib/python3.8/dist-packages/requests/sessions.py", line 542, in request
    resp = self.send(prep, **send_kwargs)
  File "/usr/local/lib/python3.8/dist-packages/requests/sessions.py", line 655, in send
    r = adapter.send(request, **kwargs)
  File "/usr/local/lib/python3.8/dist-packages/requests/adapters.py", line 529, in send
    raise ReadTimeout(e, request=request)
requests.exceptions.ReadTimeout: HTTPConnectionPool(host='115.145.177.104', port=1827): Read timed out. (read timeout=2)
ERROR:uvicorn.error:Exception in ASGI application
Traceback (most recent call last):
  File "/usr/local/lib/python3.8/dist-packages/uvicorn/protocols/http/h11_impl.py", line 373, in run_asgi
    result = await app(self.scope, self.receive, self.send)
  File "/usr/local/lib/python3.8/dist-packages/uvicorn/middleware/proxy_headers.py", line 75, in __call__
    return await self.app(scope, receive, send)
  File "/usr/local/lib/python3.8/dist-packages/fastapi/applications.py", line 208, in __call__
    await super().__call__(scope, receive, send)
  File "/usr/local/lib/python3.8/dist-packages/starlette/applications.py", line 112, in __call__
    await self.middleware_stack(scope, receive, send)
  File "/usr/local/lib/python3.8/dist-packages/starlette/middleware/errors.py", line 181, in __call__
    raise exc from None
  File "/usr/local/lib/python3.8/dist-packages/starlette/middleware/errors.py", line 159, in __call__
    await self.app(scope, receive, _send)
  File "/usr/local/lib/python3.8/dist-packages/starlette/middleware/cors.py", line 86, in __call__
    await self.simple_response(scope, receive, send, request_headers=headers)
  File "/usr/local/lib/python3.8/dist-packages/starlette/middleware/cors.py", line 142, in simple_response
    await self.app(scope, receive, send)
  File "/usr/local/lib/python3.8/dist-packages/starlette/exceptions.py", line 82, in __call__
    raise exc from None
  File "/usr/local/lib/python3.8/dist-packages/starlette/exceptions.py", line 71, in __call__
    await self.app(scope, receive, sender)
  File "/usr/local/lib/python3.8/dist-packages/starlette/routing.py", line 580, in __call__
    await route.handle(scope, receive, send)
  File "/usr/local/lib/python3.8/dist-packages/starlette/routing.py", line 241, in handle
    await self.app(scope, receive, send)
  File "/usr/local/lib/python3.8/dist-packages/starlette/routing.py", line 52, in app
    response = await func(request)
  File "/usr/local/lib/python3.8/dist-packages/fastapi/routing.py", line 226, in app
    raw_response = await run_endpoint_function(
  File "/usr/local/lib/python3.8/dist-packages/fastapi/routing.py", line 159, in run_endpoint_function
    return await dependant.call(**values)
  File "/root/rcs_api_server/app/routes/set_data.py", line 63, in set_command
    response=requests.post(url, json=command, headers=headers, timeout=2)
  File "/usr/local/lib/python3.8/dist-packages/requests/api.py", line 117, in post
    return request('post', url, data=data, json=json, **kwargs)
  File "/usr/local/lib/python3.8/dist-packages/requests/api.py", line 61, in request
    return session.request(method=method, url=url, **kwargs)
  File "/usr/local/lib/python3.8/dist-packages/requests/sessions.py", line 542, in request
    resp = self.send(prep, **send_kwargs)
  File "/usr/local/lib/python3.8/dist-packages/requests/sessions.py", line 655, in send
    r = adapter.send(request, **kwargs)
  File "/usr/local/lib/python3.8/dist-packages/requests/adapters.py", line 529, in send
    raise ReadTimeout(e, request=request)
requests.exceptions.ReadTimeout: HTTPConnectionPool(host='115.145.177.104', port=1827): Read timed out. (read timeout=2)
INFO:     115.145.177.104:59746 - "POST /set/set_command HTTP/1.1" 200 OK
INFO:     115.145.177.104:60052 - "POST /set/set_command HTTP/1.1" 200 OK
INFO:     115.145.177.104:60206 - "POST /set/set_command HTTP/1.1" 200 OK
INFO:     115.145.177.104:60420 - "POST /set/set_command HTTP/1.1" 200 OK
INFO:     115.145.177.104:60692 - "POST /set/set_command HTTP/1.1" 200 OK
INFO:     115.145.177.104:60866 - "POST /set/set_command HTTP/1.1" 200 OK
INFO:     115.145.177.104:32880 - "POST /set/set_command HTTP/1.1" 500 Internal Server Error
ERROR:    Exception in ASGI application
Traceback (most recent call last):
  File "/usr/local/lib/python3.8/dist-packages/uvicorn/protocols/http/h11_impl.py", line 373, in run_asgi
    result = await app(self.scope, self.receive, self.send)
  File "/usr/local/lib/python3.8/dist-packages/uvicorn/middleware/proxy_headers.py", line 75, in __call__
    return await self.app(scope, receive, send)
  File "/usr/local/lib/python3.8/dist-packages/fastapi/applications.py", line 208, in __call__
    await super().__call__(scope, receive, send)
  File "/usr/local/lib/python3.8/dist-packages/starlette/applications.py", line 112, in __call__
    await self.middleware_stack(scope, receive, send)
  File "/usr/local/lib/python3.8/dist-packages/starlette/middleware/errors.py", line 181, in __call__
    raise exc from None
  File "/usr/local/lib/python3.8/dist-packages/starlette/middleware/errors.py", line 159, in __call__
    await self.app(scope, receive, _send)
  File "/usr/local/lib/python3.8/dist-packages/starlette/middleware/cors.py", line 86, in __call__
    await self.simple_response(scope, receive, send, request_headers=headers)
  File "/usr/local/lib/python3.8/dist-packages/starlette/middleware/cors.py", line 142, in simple_response
    await self.app(scope, receive, send)
  File "/usr/local/lib/python3.8/dist-packages/starlette/exceptions.py", line 82, in __call__
    raise exc from None
  File "/usr/local/lib/python3.8/dist-packages/starlette/exceptions.py", line 71, in __call__
    await self.app(scope, receive, sender)
  File "/usr/local/lib/python3.8/dist-packages/starlette/routing.py", line 580, in __call__
    await route.handle(scope, receive, send)
  File "/usr/local/lib/python3.8/dist-packages/starlette/routing.py", line 241, in handle
    await self.app(scope, receive, send)
  File "/usr/local/lib/python3.8/dist-packages/starlette/routing.py", line 52, in app
    response = await func(request)
  File "/usr/local/lib/python3.8/dist-packages/fastapi/routing.py", line 226, in app
    raw_response = await run_endpoint_function(
  File "/usr/local/lib/python3.8/dist-packages/fastapi/routing.py", line 159, in run_endpoint_function
    return await dependant.call(**values)
  File "/root/rcs_api_server/app/routes/set_data.py", line 63, in set_command
    response=requests.post(url, json=command, headers=headers, timeout=2)
  File "/usr/local/lib/python3.8/dist-packages/requests/api.py", line 117, in post
    return request('post', url, data=data, json=json, **kwargs)
  File "/usr/local/lib/python3.8/dist-packages/requests/api.py", line 61, in request
    return session.request(method=method, url=url, **kwargs)
  File "/usr/local/lib/python3.8/dist-packages/requests/sessions.py", line 542, in request
    resp = self.send(prep, **send_kwargs)
  File "/usr/local/lib/python3.8/dist-packages/requests/sessions.py", line 655, in send
    r = adapter.send(request, **kwargs)
  File "/usr/local/lib/python3.8/dist-packages/requests/adapters.py", line 529, in send
    raise ReadTimeout(e, request=request)
requests.exceptions.ReadTimeout: HTTPConnectionPool(host='115.145.177.104', port=1827): Read timed out. (read timeout=2)
ERROR:uvicorn.error:Exception in ASGI application
Traceback (most recent call last):
  File "/usr/local/lib/python3.8/dist-packages/uvicorn/protocols/http/h11_impl.py", line 373, in run_asgi
    result = await app(self.scope, self.receive, self.send)
  File "/usr/local/lib/python3.8/dist-packages/uvicorn/middleware/proxy_headers.py", line 75, in __call__
    return await self.app(scope, receive, send)
  File "/usr/local/lib/python3.8/dist-packages/fastapi/applications.py", line 208, in __call__
    await super().__call__(scope, receive, send)
  File "/usr/local/lib/python3.8/dist-packages/starlette/applications.py", line 112, in __call__
    await self.middleware_stack(scope, receive, send)
  File "/usr/local/lib/python3.8/dist-packages/starlette/middleware/errors.py", line 181, in __call__
    raise exc from None
  File "/usr/local/lib/python3.8/dist-packages/starlette/middleware/errors.py", line 159, in __call__
    await self.app(scope, receive, _send)
  File "/usr/local/lib/python3.8/dist-packages/starlette/middleware/cors.py", line 86, in __call__
    await self.simple_response(scope, receive, send, request_headers=headers)
  File "/usr/local/lib/python3.8/dist-packages/starlette/middleware/cors.py", line 142, in simple_response
    await self.app(scope, receive, send)
  File "/usr/local/lib/python3.8/dist-packages/starlette/exceptions.py", line 82, in __call__
    raise exc from None
  File "/usr/local/lib/python3.8/dist-packages/starlette/exceptions.py", line 71, in __call__
    await self.app(scope, receive, sender)
  File "/usr/local/lib/python3.8/dist-packages/starlette/routing.py", line 580, in __call__
    await route.handle(scope, receive, send)
  File "/usr/local/lib/python3.8/dist-packages/starlette/routing.py", line 241, in handle
    await self.app(scope, receive, send)
  File "/usr/local/lib/python3.8/dist-packages/starlette/routing.py", line 52, in app
    response = await func(request)
  File "/usr/local/lib/python3.8/dist-packages/fastapi/routing.py", line 226, in app
    raw_response = await run_endpoint_function(
  File "/usr/local/lib/python3.8/dist-packages/fastapi/routing.py", line 159, in run_endpoint_function
    return await dependant.call(**values)
  File "/root/rcs_api_server/app/routes/set_data.py", line 63, in set_command
    response=requests.post(url, json=command, headers=headers, timeout=2)
  File "/usr/local/lib/python3.8/dist-packages/requests/api.py", line 117, in post
    return request('post', url, data=data, json=json, **kwargs)
  File "/usr/local/lib/python3.8/dist-packages/requests/api.py", line 61, in request
    return session.request(method=method, url=url, **kwargs)
  File "/usr/local/lib/python3.8/dist-packages/requests/sessions.py", line 542, in request
    resp = self.send(prep, **send_kwargs)
  File "/usr/local/lib/python3.8/dist-packages/requests/sessions.py", line 655, in send
    r = adapter.send(request, **kwargs)
  File "/usr/local/lib/python3.8/dist-packages/requests/adapters.py", line 529, in send
    raise ReadTimeout(e, request=request)
requests.exceptions.ReadTimeout: HTTPConnectionPool(host='115.145.177.104', port=1827): Read timed out. (read timeout=2)
INFO:     115.145.177.104:33744 - "POST /set/set_command HTTP/1.1" 200 OK
INFO:     115.145.177.104:34230 - "POST /set/set_command HTTP/1.1" 500 Internal Server Error
ERROR:    Exception in ASGI application
Traceback (most recent call last):
  File "/usr/local/lib/python3.8/dist-packages/uvicorn/protocols/http/h11_impl.py", line 373, in run_asgi
    result = await app(self.scope, self.receive, self.send)
  File "/usr/local/lib/python3.8/dist-packages/uvicorn/middleware/proxy_headers.py", line 75, in __call__
    return await self.app(scope, receive, send)
  File "/usr/local/lib/python3.8/dist-packages/fastapi/applications.py", line 208, in __call__
    await super().__call__(scope, receive, send)
  File "/usr/local/lib/python3.8/dist-packages/starlette/applications.py", line 112, in __call__
    await self.middleware_stack(scope, receive, send)
  File "/usr/local/lib/python3.8/dist-packages/starlette/middleware/errors.py", line 181, in __call__
    raise exc from None
  File "/usr/local/lib/python3.8/dist-packages/starlette/middleware/errors.py", line 159, in __call__
    await self.app(scope, receive, _send)
  File "/usr/local/lib/python3.8/dist-packages/starlette/middleware/cors.py", line 86, in __call__
    await self.simple_response(scope, receive, send, request_headers=headers)
  File "/usr/local/lib/python3.8/dist-packages/starlette/middleware/cors.py", line 142, in simple_response
    await self.app(scope, receive, send)
  File "/usr/local/lib/python3.8/dist-packages/starlette/exceptions.py", line 82, in __call__
    raise exc from None
  File "/usr/local/lib/python3.8/dist-packages/starlette/exceptions.py", line 71, in __call__
    await self.app(scope, receive, sender)
  File "/usr/local/lib/python3.8/dist-packages/starlette/routing.py", line 580, in __call__
    await route.handle(scope, receive, send)
  File "/usr/local/lib/python3.8/dist-packages/starlette/routing.py", line 241, in handle
    await self.app(scope, receive, send)
  File "/usr/local/lib/python3.8/dist-packages/starlette/routing.py", line 52, in app
    response = await func(request)
  File "/usr/local/lib/python3.8/dist-packages/fastapi/routing.py", line 226, in app
    raw_response = await run_endpoint_function(
  File "/usr/local/lib/python3.8/dist-packages/fastapi/routing.py", line 159, in run_endpoint_function
    return await dependant.call(**values)
  File "/root/rcs_api_server/app/routes/set_data.py", line 63, in set_command
    response=requests.post(url, json=command, headers=headers, timeout=2)
  File "/usr/local/lib/python3.8/dist-packages/requests/api.py", line 117, in post
    return request('post', url, data=data, json=json, **kwargs)
  File "/usr/local/lib/python3.8/dist-packages/requests/api.py", line 61, in request
    return session.request(method=method, url=url, **kwargs)
  File "/usr/local/lib/python3.8/dist-packages/requests/sessions.py", line 542, in request
    resp = self.send(prep, **send_kwargs)
  File "/usr/local/lib/python3.8/dist-packages/requests/sessions.py", line 655, in send
    r = adapter.send(request, **kwargs)
  File "/usr/local/lib/python3.8/dist-packages/requests/adapters.py", line 498, in send
    raise ConnectionError(err, request=request)
requests.exceptions.ConnectionError: ('Connection aborted.', RemoteDisconnected('Remote end closed connection without response'))
ERROR:uvicorn.error:Exception in ASGI application
Traceback (most recent call last):
  File "/usr/local/lib/python3.8/dist-packages/uvicorn/protocols/http/h11_impl.py", line 373, in run_asgi
    result = await app(self.scope, self.receive, self.send)
  File "/usr/local/lib/python3.8/dist-packages/uvicorn/middleware/proxy_headers.py", line 75, in __call__
    return await self.app(scope, receive, send)
  File "/usr/local/lib/python3.8/dist-packages/fastapi/applications.py", line 208, in __call__
    await super().__call__(scope, receive, send)
  File "/usr/local/lib/python3.8/dist-packages/starlette/applications.py", line 112, in __call__
    await self.middleware_stack(scope, receive, send)
  File "/usr/local/lib/python3.8/dist-packages/starlette/middleware/errors.py", line 181, in __call__
    raise exc from None
  File "/usr/local/lib/python3.8/dist-packages/starlette/middleware/errors.py", line 159, in __call__
    await self.app(scope, receive, _send)
  File "/usr/local/lib/python3.8/dist-packages/starlette/middleware/cors.py", line 86, in __call__
    await self.simple_response(scope, receive, send, request_headers=headers)
  File "/usr/local/lib/python3.8/dist-packages/starlette/middleware/cors.py", line 142, in simple_response
    await self.app(scope, receive, send)
  File "/usr/local/lib/python3.8/dist-packages/starlette/exceptions.py", line 82, in __call__
    raise exc from None
  File "/usr/local/lib/python3.8/dist-packages/starlette/exceptions.py", line 71, in __call__
    await self.app(scope, receive, sender)
  File "/usr/local/lib/python3.8/dist-packages/starlette/routing.py", line 580, in __call__
    await route.handle(scope, receive, send)
  File "/usr/local/lib/python3.8/dist-packages/starlette/routing.py", line 241, in handle
    await self.app(scope, receive, send)
  File "/usr/local/lib/python3.8/dist-packages/starlette/routing.py", line 52, in app
    response = await func(request)
  File "/usr/local/lib/python3.8/dist-packages/fastapi/routing.py", line 226, in app
    raw_response = await run_endpoint_function(
  File "/usr/local/lib/python3.8/dist-packages/fastapi/routing.py", line 159, in run_endpoint_function
    return await dependant.call(**values)
  File "/root/rcs_api_server/app/routes/set_data.py", line 63, in set_command
    response=requests.post(url, json=command, headers=headers, timeout=2)
  File "/usr/local/lib/python3.8/dist-packages/requests/api.py", line 117, in post
    return request('post', url, data=data, json=json, **kwargs)
  File "/usr/local/lib/python3.8/dist-packages/requests/api.py", line 61, in request
    return session.request(method=method, url=url, **kwargs)
  File "/usr/local/lib/python3.8/dist-packages/requests/sessions.py", line 542, in request
    resp = self.send(prep, **send_kwargs)
  File "/usr/local/lib/python3.8/dist-packages/requests/sessions.py", line 655, in send
    r = adapter.send(request, **kwargs)
  File "/usr/local/lib/python3.8/dist-packages/requests/adapters.py", line 498, in send
    raise ConnectionError(err, request=request)
requests.exceptions.ConnectionError: ('Connection aborted.', RemoteDisconnected('Remote end closed connection without response'))
INFO:     115.145.177.104:40918 - "POST /set/set_command HTTP/1.1" 500 Internal Server Error
ERROR:    Exception in ASGI application
Traceback (most recent call last):
  File "/usr/local/lib/python3.8/dist-packages/uvicorn/protocols/http/h11_impl.py", line 373, in run_asgi
    result = await app(self.scope, self.receive, self.send)
  File "/usr/local/lib/python3.8/dist-packages/uvicorn/middleware/proxy_headers.py", line 75, in __call__
    return await self.app(scope, receive, send)
  File "/usr/local/lib/python3.8/dist-packages/fastapi/applications.py", line 208, in __call__
    await super().__call__(scope, receive, send)
  File "/usr/local/lib/python3.8/dist-packages/starlette/applications.py", line 112, in __call__
    await self.middleware_stack(scope, receive, send)
  File "/usr/local/lib/python3.8/dist-packages/starlette/middleware/errors.py", line 181, in __call__
    raise exc from None
  File "/usr/local/lib/python3.8/dist-packages/starlette/middleware/errors.py", line 159, in __call__
    await self.app(scope, receive, _send)
  File "/usr/local/lib/python3.8/dist-packages/starlette/middleware/cors.py", line 86, in __call__
    await self.simple_response(scope, receive, send, request_headers=headers)
  File "/usr/local/lib/python3.8/dist-packages/starlette/middleware/cors.py", line 142, in simple_response
    await self.app(scope, receive, send)
  File "/usr/local/lib/python3.8/dist-packages/starlette/exceptions.py", line 82, in __call__
    raise exc from None
  File "/usr/local/lib/python3.8/dist-packages/starlette/exceptions.py", line 71, in __call__
    await self.app(scope, receive, sender)
  File "/usr/local/lib/python3.8/dist-packages/starlette/routing.py", line 580, in __call__
    await route.handle(scope, receive, send)
  File "/usr/local/lib/python3.8/dist-packages/starlette/routing.py", line 241, in handle
    await self.app(scope, receive, send)
  File "/usr/local/lib/python3.8/dist-packages/starlette/routing.py", line 52, in app
    response = await func(request)
  File "/usr/local/lib/python3.8/dist-packages/fastapi/routing.py", line 226, in app
    raw_response = await run_endpoint_function(
  File "/usr/local/lib/python3.8/dist-packages/fastapi/routing.py", line 159, in run_endpoint_function
    return await dependant.call(**values)
  File "/root/rcs_api_server/app/routes/set_data.py", line 63, in set_command
    response=requests.post(url, json=command, headers=headers, timeout=2)
  File "/usr/local/lib/python3.8/dist-packages/requests/api.py", line 117, in post
    return request('post', url, data=data, json=json, **kwargs)
  File "/usr/local/lib/python3.8/dist-packages/requests/api.py", line 61, in request
    return session.request(method=method, url=url, **kwargs)
  File "/usr/local/lib/python3.8/dist-packages/requests/sessions.py", line 542, in request
    resp = self.send(prep, **send_kwargs)
  File "/usr/local/lib/python3.8/dist-packages/requests/sessions.py", line 655, in send
    r = adapter.send(request, **kwargs)
  File "/usr/local/lib/python3.8/dist-packages/requests/adapters.py", line 498, in send
    raise ConnectionError(err, request=request)
requests.exceptions.ConnectionError: ('Connection aborted.', RemoteDisconnected('Remote end closed connection without response'))
ERROR:uvicorn.error:Exception in ASGI application
Traceback (most recent call last):
  File "/usr/local/lib/python3.8/dist-packages/uvicorn/protocols/http/h11_impl.py", line 373, in run_asgi
    result = await app(self.scope, self.receive, self.send)
  File "/usr/local/lib/python3.8/dist-packages/uvicorn/middleware/proxy_headers.py", line 75, in __call__
    return await self.app(scope, receive, send)
  File "/usr/local/lib/python3.8/dist-packages/fastapi/applications.py", line 208, in __call__
    await super().__call__(scope, receive, send)
  File "/usr/local/lib/python3.8/dist-packages/starlette/applications.py", line 112, in __call__
    await self.middleware_stack(scope, receive, send)
  File "/usr/local/lib/python3.8/dist-packages/starlette/middleware/errors.py", line 181, in __call__
    raise exc from None
  File "/usr/local/lib/python3.8/dist-packages/starlette/middleware/errors.py", line 159, in __call__
    await self.app(scope, receive, _send)
  File "/usr/local/lib/python3.8/dist-packages/starlette/middleware/cors.py", line 86, in __call__
    await self.simple_response(scope, receive, send, request_headers=headers)
  File "/usr/local/lib/python3.8/dist-packages/starlette/middleware/cors.py", line 142, in simple_response
    await self.app(scope, receive, send)
  File "/usr/local/lib/python3.8/dist-packages/starlette/exceptions.py", line 82, in __call__
    raise exc from None
  File "/usr/local/lib/python3.8/dist-packages/starlette/exceptions.py", line 71, in __call__
    await self.app(scope, receive, sender)
  File "/usr/local/lib/python3.8/dist-packages/starlette/routing.py", line 580, in __call__
    await route.handle(scope, receive, send)
  File "/usr/local/lib/python3.8/dist-packages/starlette/routing.py", line 241, in handle
    await self.app(scope, receive, send)
  File "/usr/local/lib/python3.8/dist-packages/starlette/routing.py", line 52, in app
    response = await func(request)
  File "/usr/local/lib/python3.8/dist-packages/fastapi/routing.py", line 226, in app
    raw_response = await run_endpoint_function(
  File "/usr/local/lib/python3.8/dist-packages/fastapi/routing.py", line 159, in run_endpoint_function
    return await dependant.call(**values)
  File "/root/rcs_api_server/app/routes/set_data.py", line 63, in set_command
    response=requests.post(url, json=command, headers=headers, timeout=2)
  File "/usr/local/lib/python3.8/dist-packages/requests/api.py", line 117, in post
    return request('post', url, data=data, json=json, **kwargs)
  File "/usr/local/lib/python3.8/dist-packages/requests/api.py", line 61, in request
    return session.request(method=method, url=url, **kwargs)
  File "/usr/local/lib/python3.8/dist-packages/requests/sessions.py", line 542, in request
    resp = self.send(prep, **send_kwargs)
  File "/usr/local/lib/python3.8/dist-packages/requests/sessions.py", line 655, in send
    r = adapter.send(request, **kwargs)
  File "/usr/local/lib/python3.8/dist-packages/requests/adapters.py", line 498, in send
    raise ConnectionError(err, request=request)
requests.exceptions.ConnectionError: ('Connection aborted.', RemoteDisconnected('Remote end closed connection without response'))
INFO:     115.145.177.104:42520 - "POST /set/set_command HTTP/1.1" 200 OK
INFO:     115.145.177.104:43006 - "POST /set/set_command HTTP/1.1" 200 OK
INFO:     115.145.177.104:43130 - "POST /set/set_command HTTP/1.1" 200 OK
INFO:     115.145.177.104:43256 - "POST /set/set_command HTTP/1.1" 200 OK
INFO:     115.145.177.104:54628 - "POST /set/set_command HTTP/1.1" 200 OK
INFO:     115.145.177.104:54748 - "POST /set/set_command HTTP/1.1" 500 Internal Server Error
ERROR:    Exception in ASGI application
Traceback (most recent call last):
  File "/usr/local/lib/python3.8/dist-packages/uvicorn/protocols/http/h11_impl.py", line 373, in run_asgi
    result = await app(self.scope, self.receive, self.send)
  File "/usr/local/lib/python3.8/dist-packages/uvicorn/middleware/proxy_headers.py", line 75, in __call__
    return await self.app(scope, receive, send)
  File "/usr/local/lib/python3.8/dist-packages/fastapi/applications.py", line 208, in __call__
    await super().__call__(scope, receive, send)
  File "/usr/local/lib/python3.8/dist-packages/starlette/applications.py", line 112, in __call__
    await self.middleware_stack(scope, receive, send)
  File "/usr/local/lib/python3.8/dist-packages/starlette/middleware/errors.py", line 181, in __call__
    raise exc from None
  File "/usr/local/lib/python3.8/dist-packages/starlette/middleware/errors.py", line 159, in __call__
    await self.app(scope, receive, _send)
  File "/usr/local/lib/python3.8/dist-packages/starlette/middleware/cors.py", line 86, in __call__
    await self.simple_response(scope, receive, send, request_headers=headers)
  File "/usr/local/lib/python3.8/dist-packages/starlette/middleware/cors.py", line 142, in simple_response
    await self.app(scope, receive, send)
  File "/usr/local/lib/python3.8/dist-packages/starlette/exceptions.py", line 82, in __call__
    raise exc from None
  File "/usr/local/lib/python3.8/dist-packages/starlette/exceptions.py", line 71, in __call__
    await self.app(scope, receive, sender)
  File "/usr/local/lib/python3.8/dist-packages/starlette/routing.py", line 580, in __call__
    await route.handle(scope, receive, send)
  File "/usr/local/lib/python3.8/dist-packages/starlette/routing.py", line 241, in handle
    await self.app(scope, receive, send)
  File "/usr/local/lib/python3.8/dist-packages/starlette/routing.py", line 52, in app
    response = await func(request)
  File "/usr/local/lib/python3.8/dist-packages/fastapi/routing.py", line 226, in app
    raw_response = await run_endpoint_function(
  File "/usr/local/lib/python3.8/dist-packages/fastapi/routing.py", line 159, in run_endpoint_function
    return await dependant.call(**values)
  File "/root/rcs_api_server/app/routes/set_data.py", line 63, in set_command
    response=requests.post(url, json=command, headers=headers, timeout=2)
  File "/usr/local/lib/python3.8/dist-packages/requests/api.py", line 117, in post
    return request('post', url, data=data, json=json, **kwargs)
  File "/usr/local/lib/python3.8/dist-packages/requests/api.py", line 61, in request
    return session.request(method=method, url=url, **kwargs)
  File "/usr/local/lib/python3.8/dist-packages/requests/sessions.py", line 542, in request
    resp = self.send(prep, **send_kwargs)
  File "/usr/local/lib/python3.8/dist-packages/requests/sessions.py", line 655, in send
    r = adapter.send(request, **kwargs)
  File "/usr/local/lib/python3.8/dist-packages/requests/adapters.py", line 529, in send
    raise ReadTimeout(e, request=request)
requests.exceptions.ReadTimeout: HTTPConnectionPool(host='115.145.177.104', port=1827): Read timed out. (read timeout=2)
ERROR:uvicorn.error:Exception in ASGI application
Traceback (most recent call last):
  File "/usr/local/lib/python3.8/dist-packages/uvicorn/protocols/http/h11_impl.py", line 373, in run_asgi
    result = await app(self.scope, self.receive, self.send)
  File "/usr/local/lib/python3.8/dist-packages/uvicorn/middleware/proxy_headers.py", line 75, in __call__
    return await self.app(scope, receive, send)
  File "/usr/local/lib/python3.8/dist-packages/fastapi/applications.py", line 208, in __call__
    await super().__call__(scope, receive, send)
  File "/usr/local/lib/python3.8/dist-packages/starlette/applications.py", line 112, in __call__
    await self.middleware_stack(scope, receive, send)
  File "/usr/local/lib/python3.8/dist-packages/starlette/middleware/errors.py", line 181, in __call__
    raise exc from None
  File "/usr/local/lib/python3.8/dist-packages/starlette/middleware/errors.py", line 159, in __call__
    await self.app(scope, receive, _send)
  File "/usr/local/lib/python3.8/dist-packages/starlette/middleware/cors.py", line 86, in __call__
    await self.simple_response(scope, receive, send, request_headers=headers)
  File "/usr/local/lib/python3.8/dist-packages/starlette/middleware/cors.py", line 142, in simple_response
    await self.app(scope, receive, send)
  File "/usr/local/lib/python3.8/dist-packages/starlette/exceptions.py", line 82, in __call__
    raise exc from None
  File "/usr/local/lib/python3.8/dist-packages/starlette/exceptions.py", line 71, in __call__
    await self.app(scope, receive, sender)
  File "/usr/local/lib/python3.8/dist-packages/starlette/routing.py", line 580, in __call__
    await route.handle(scope, receive, send)
  File "/usr/local/lib/python3.8/dist-packages/starlette/routing.py", line 241, in handle
    await self.app(scope, receive, send)
  File "/usr/local/lib/python3.8/dist-packages/starlette/routing.py", line 52, in app
    response = await func(request)
  File "/usr/local/lib/python3.8/dist-packages/fastapi/routing.py", line 226, in app
    raw_response = await run_endpoint_function(
  File "/usr/local/lib/python3.8/dist-packages/fastapi/routing.py", line 159, in run_endpoint_function
    return await dependant.call(**values)
  File "/root/rcs_api_server/app/routes/set_data.py", line 63, in set_command
    response=requests.post(url, json=command, headers=headers, timeout=2)
  File "/usr/local/lib/python3.8/dist-packages/requests/api.py", line 117, in post
    return request('post', url, data=data, json=json, **kwargs)
  File "/usr/local/lib/python3.8/dist-packages/requests/api.py", line 61, in request
    return session.request(method=method, url=url, **kwargs)
  File "/usr/local/lib/python3.8/dist-packages/requests/sessions.py", line 542, in request
    resp = self.send(prep, **send_kwargs)
  File "/usr/local/lib/python3.8/dist-packages/requests/sessions.py", line 655, in send
    r = adapter.send(request, **kwargs)
  File "/usr/local/lib/python3.8/dist-packages/requests/adapters.py", line 529, in send
    raise ReadTimeout(e, request=request)
requests.exceptions.ReadTimeout: HTTPConnectionPool(host='115.145.177.104', port=1827): Read timed out. (read timeout=2)
INFO:     115.145.177.104:55150 - "POST /set/set_command HTTP/1.1" 500 Internal Server Error
ERROR:    Exception in ASGI application
Traceback (most recent call last):
  File "/usr/local/lib/python3.8/dist-packages/uvicorn/protocols/http/h11_impl.py", line 373, in run_asgi
    result = await app(self.scope, self.receive, self.send)
  File "/usr/local/lib/python3.8/dist-packages/uvicorn/middleware/proxy_headers.py", line 75, in __call__
    return await self.app(scope, receive, send)
  File "/usr/local/lib/python3.8/dist-packages/fastapi/applications.py", line 208, in __call__
    await super().__call__(scope, receive, send)
  File "/usr/local/lib/python3.8/dist-packages/starlette/applications.py", line 112, in __call__
    await self.middleware_stack(scope, receive, send)
  File "/usr/local/lib/python3.8/dist-packages/starlette/middleware/errors.py", line 181, in __call__
    raise exc from None
  File "/usr/local/lib/python3.8/dist-packages/starlette/middleware/errors.py", line 159, in __call__
    await self.app(scope, receive, _send)
  File "/usr/local/lib/python3.8/dist-packages/starlette/middleware/cors.py", line 86, in __call__
    await self.simple_response(scope, receive, send, request_headers=headers)
  File "/usr/local/lib/python3.8/dist-packages/starlette/middleware/cors.py", line 142, in simple_response
    await self.app(scope, receive, send)
  File "/usr/local/lib/python3.8/dist-packages/starlette/exceptions.py", line 82, in __call__
    raise exc from None
  File "/usr/local/lib/python3.8/dist-packages/starlette/exceptions.py", line 71, in __call__
    await self.app(scope, receive, sender)
  File "/usr/local/lib/python3.8/dist-packages/starlette/routing.py", line 580, in __call__
    await route.handle(scope, receive, send)
  File "/usr/local/lib/python3.8/dist-packages/starlette/routing.py", line 241, in handle
    await self.app(scope, receive, send)
  File "/usr/local/lib/python3.8/dist-packages/starlette/routing.py", line 52, in app
    response = await func(request)
  File "/usr/local/lib/python3.8/dist-packages/fastapi/routing.py", line 226, in app
    raw_response = await run_endpoint_function(
  File "/usr/local/lib/python3.8/dist-packages/fastapi/routing.py", line 159, in run_endpoint_function
    return await dependant.call(**values)
  File "/root/rcs_api_server/app/routes/set_data.py", line 63, in set_command
    response=requests.post(url, json=command, headers=headers, timeout=2)
  File "/usr/local/lib/python3.8/dist-packages/requests/api.py", line 117, in post
    return request('post', url, data=data, json=json, **kwargs)
  File "/usr/local/lib/python3.8/dist-packages/requests/api.py", line 61, in request
    return session.request(method=method, url=url, **kwargs)
  File "/usr/local/lib/python3.8/dist-packages/requests/sessions.py", line 542, in request
    resp = self.send(prep, **send_kwargs)
  File "/usr/local/lib/python3.8/dist-packages/requests/sessions.py", line 655, in send
    r = adapter.send(request, **kwargs)
  File "/usr/local/lib/python3.8/dist-packages/requests/adapters.py", line 529, in send
    raise ReadTimeout(e, request=request)
requests.exceptions.ReadTimeout: HTTPConnectionPool(host='115.145.177.104', port=1827): Read timed out. (read timeout=2)
ERROR:uvicorn.error:Exception in ASGI application
Traceback (most recent call last):
  File "/usr/local/lib/python3.8/dist-packages/uvicorn/protocols/http/h11_impl.py", line 373, in run_asgi
    result = await app(self.scope, self.receive, self.send)
  File "/usr/local/lib/python3.8/dist-packages/uvicorn/middleware/proxy_headers.py", line 75, in __call__
    return await self.app(scope, receive, send)
  File "/usr/local/lib/python3.8/dist-packages/fastapi/applications.py", line 208, in __call__
    await super().__call__(scope, receive, send)
  File "/usr/local/lib/python3.8/dist-packages/starlette/applications.py", line 112, in __call__
    await self.middleware_stack(scope, receive, send)
  File "/usr/local/lib/python3.8/dist-packages/starlette/middleware/errors.py", line 181, in __call__
    raise exc from None
  File "/usr/local/lib/python3.8/dist-packages/starlette/middleware/errors.py", line 159, in __call__
    await self.app(scope, receive, _send)
  File "/usr/local/lib/python3.8/dist-packages/starlette/middleware/cors.py", line 86, in __call__
    await self.simple_response(scope, receive, send, request_headers=headers)
  File "/usr/local/lib/python3.8/dist-packages/starlette/middleware/cors.py", line 142, in simple_response
    await self.app(scope, receive, send)
  File "/usr/local/lib/python3.8/dist-packages/starlette/exceptions.py", line 82, in __call__
    raise exc from None
  File "/usr/local/lib/python3.8/dist-packages/starlette/exceptions.py", line 71, in __call__
    await self.app(scope, receive, sender)
  File "/usr/local/lib/python3.8/dist-packages/starlette/routing.py", line 580, in __call__
    await route.handle(scope, receive, send)
  File "/usr/local/lib/python3.8/dist-packages/starlette/routing.py", line 241, in handle
    await self.app(scope, receive, send)
  File "/usr/local/lib/python3.8/dist-packages/starlette/routing.py", line 52, in app
    response = await func(request)
  File "/usr/local/lib/python3.8/dist-packages/fastapi/routing.py", line 226, in app
    raw_response = await run_endpoint_function(
  File "/usr/local/lib/python3.8/dist-packages/fastapi/routing.py", line 159, in run_endpoint_function
    return await dependant.call(**values)
  File "/root/rcs_api_server/app/routes/set_data.py", line 63, in set_command
    response=requests.post(url, json=command, headers=headers, timeout=2)
  File "/usr/local/lib/python3.8/dist-packages/requests/api.py", line 117, in post
    return request('post', url, data=data, json=json, **kwargs)
  File "/usr/local/lib/python3.8/dist-packages/requests/api.py", line 61, in request
    return session.request(method=method, url=url, **kwargs)
  File "/usr/local/lib/python3.8/dist-packages/requests/sessions.py", line 542, in request
    resp = self.send(prep, **send_kwargs)
  File "/usr/local/lib/python3.8/dist-packages/requests/sessions.py", line 655, in send
    r = adapter.send(request, **kwargs)
  File "/usr/local/lib/python3.8/dist-packages/requests/adapters.py", line 529, in send
    raise ReadTimeout(e, request=request)
requests.exceptions.ReadTimeout: HTTPConnectionPool(host='115.145.177.104', port=1827): Read timed out. (read timeout=2)
INFO:     115.145.177.104:55692 - "POST /set/set_command HTTP/1.1" 500 Internal Server Error
ERROR:    Exception in ASGI application
Traceback (most recent call last):
  File "/usr/local/lib/python3.8/dist-packages/uvicorn/protocols/http/h11_impl.py", line 373, in run_asgi
    result = await app(self.scope, self.receive, self.send)
  File "/usr/local/lib/python3.8/dist-packages/uvicorn/middleware/proxy_headers.py", line 75, in __call__
    return await self.app(scope, receive, send)
  File "/usr/local/lib/python3.8/dist-packages/fastapi/applications.py", line 208, in __call__
    await super().__call__(scope, receive, send)
  File "/usr/local/lib/python3.8/dist-packages/starlette/applications.py", line 112, in __call__
    await self.middleware_stack(scope, receive, send)
  File "/usr/local/lib/python3.8/dist-packages/starlette/middleware/errors.py", line 181, in __call__
    raise exc from None
  File "/usr/local/lib/python3.8/dist-packages/starlette/middleware/errors.py", line 159, in __call__
    await self.app(scope, receive, _send)
  File "/usr/local/lib/python3.8/dist-packages/starlette/middleware/cors.py", line 86, in __call__
    await self.simple_response(scope, receive, send, request_headers=headers)
  File "/usr/local/lib/python3.8/dist-packages/starlette/middleware/cors.py", line 142, in simple_response
    await self.app(scope, receive, send)
  File "/usr/local/lib/python3.8/dist-packages/starlette/exceptions.py", line 82, in __call__
    raise exc from None
  File "/usr/local/lib/python3.8/dist-packages/starlette/exceptions.py", line 71, in __call__
    await self.app(scope, receive, sender)
  File "/usr/local/lib/python3.8/dist-packages/starlette/routing.py", line 580, in __call__
    await route.handle(scope, receive, send)
  File "/usr/local/lib/python3.8/dist-packages/starlette/routing.py", line 241, in handle
    await self.app(scope, receive, send)
  File "/usr/local/lib/python3.8/dist-packages/starlette/routing.py", line 52, in app
    response = await func(request)
  File "/usr/local/lib/python3.8/dist-packages/fastapi/routing.py", line 226, in app
    raw_response = await run_endpoint_function(
  File "/usr/local/lib/python3.8/dist-packages/fastapi/routing.py", line 159, in run_endpoint_function
    return await dependant.call(**values)
  File "/root/rcs_api_server/app/routes/set_data.py", line 63, in set_command
    response=requests.post(url, json=command, headers=headers, timeout=2)
  File "/usr/local/lib/python3.8/dist-packages/requests/api.py", line 117, in post
    return request('post', url, data=data, json=json, **kwargs)
  File "/usr/local/lib/python3.8/dist-packages/requests/api.py", line 61, in request
    return session.request(method=method, url=url, **kwargs)
  File "/usr/local/lib/python3.8/dist-packages/requests/sessions.py", line 542, in request
    resp = self.send(prep, **send_kwargs)
  File "/usr/local/lib/python3.8/dist-packages/requests/sessions.py", line 655, in send
    r = adapter.send(request, **kwargs)
  File "/usr/local/lib/python3.8/dist-packages/requests/adapters.py", line 529, in send
    raise ReadTimeout(e, request=request)
requests.exceptions.ReadTimeout: HTTPConnectionPool(host='115.145.177.104', port=1827): Read timed out. (read timeout=2)
ERROR:uvicorn.error:Exception in ASGI application
Traceback (most recent call last):
  File "/usr/local/lib/python3.8/dist-packages/uvicorn/protocols/http/h11_impl.py", line 373, in run_asgi
    result = await app(self.scope, self.receive, self.send)
  File "/usr/local/lib/python3.8/dist-packages/uvicorn/middleware/proxy_headers.py", line 75, in __call__
    return await self.app(scope, receive, send)
  File "/usr/local/lib/python3.8/dist-packages/fastapi/applications.py", line 208, in __call__
    await super().__call__(scope, receive, send)
  File "/usr/local/lib/python3.8/dist-packages/starlette/applications.py", line 112, in __call__
    await self.middleware_stack(scope, receive, send)
  File "/usr/local/lib/python3.8/dist-packages/starlette/middleware/errors.py", line 181, in __call__
    raise exc from None
  File "/usr/local/lib/python3.8/dist-packages/starlette/middleware/errors.py", line 159, in __call__
    await self.app(scope, receive, _send)
  File "/usr/local/lib/python3.8/dist-packages/starlette/middleware/cors.py", line 86, in __call__
    await self.simple_response(scope, receive, send, request_headers=headers)
  File "/usr/local/lib/python3.8/dist-packages/starlette/middleware/cors.py", line 142, in simple_response
    await self.app(scope, receive, send)
  File "/usr/local/lib/python3.8/dist-packages/starlette/exceptions.py", line 82, in __call__
    raise exc from None
  File "/usr/local/lib/python3.8/dist-packages/starlette/exceptions.py", line 71, in __call__
    await self.app(scope, receive, sender)
  File "/usr/local/lib/python3.8/dist-packages/starlette/routing.py", line 580, in __call__
    await route.handle(scope, receive, send)
  File "/usr/local/lib/python3.8/dist-packages/starlette/routing.py", line 241, in handle
    await self.app(scope, receive, send)
  File "/usr/local/lib/python3.8/dist-packages/starlette/routing.py", line 52, in app
    response = await func(request)
  File "/usr/local/lib/python3.8/dist-packages/fastapi/routing.py", line 226, in app
    raw_response = await run_endpoint_function(
  File "/usr/local/lib/python3.8/dist-packages/fastapi/routing.py", line 159, in run_endpoint_function
    return await dependant.call(**values)
  File "/root/rcs_api_server/app/routes/set_data.py", line 63, in set_command
    response=requests.post(url, json=command, headers=headers, timeout=2)
  File "/usr/local/lib/python3.8/dist-packages/requests/api.py", line 117, in post
    return request('post', url, data=data, json=json, **kwargs)
  File "/usr/local/lib/python3.8/dist-packages/requests/api.py", line 61, in request
    return session.request(method=method, url=url, **kwargs)
  File "/usr/local/lib/python3.8/dist-packages/requests/sessions.py", line 542, in request
    resp = self.send(prep, **send_kwargs)
  File "/usr/local/lib/python3.8/dist-packages/requests/sessions.py", line 655, in send
    r = adapter.send(request, **kwargs)
  File "/usr/local/lib/python3.8/dist-packages/requests/adapters.py", line 529, in send
    raise ReadTimeout(e, request=request)
requests.exceptions.ReadTimeout: HTTPConnectionPool(host='115.145.177.104', port=1827): Read timed out. (read timeout=2)
INFO:     115.145.177.104:41692 - "GET /hi HTTP/1.1" 404 Not Found
INFO:     115.145.177.104:41700 - "POST /set/robot_data HTTP/1.1" 404 Not Found
INFO:     115.145.177.104:41702 - "POST /set/robot_data HTTP/1.1" 404 Not Found
INFO:     115.145.177.104:34294 - "POST /set/set_command HTTP/1.1" 200 OK
INFO:     115.145.177.104:36842 - "POST /set/set_command HTTP/1.1" 200 OK
INFO:     115.145.177.104:37196 - "POST /set/set_command HTTP/1.1" 200 OK
INFO:     115.145.177.104:38068 - "POST /set/set_command HTTP/1.1" 200 OK
INFO:     115.145.177.104:38360 - "POST /set/set_command HTTP/1.1" 200 OK
INFO:     115.145.177.104:38470 - "POST /set/set_command HTTP/1.1" 500 Internal Server Error
ERROR:    Exception in ASGI application
Traceback (most recent call last):
  File "/usr/local/lib/python3.8/dist-packages/uvicorn/protocols/http/h11_impl.py", line 373, in run_asgi
    result = await app(self.scope, self.receive, self.send)
  File "/usr/local/lib/python3.8/dist-packages/uvicorn/middleware/proxy_headers.py", line 75, in __call__
    return await self.app(scope, receive, send)
  File "/usr/local/lib/python3.8/dist-packages/fastapi/applications.py", line 208, in __call__
    await super().__call__(scope, receive, send)
  File "/usr/local/lib/python3.8/dist-packages/starlette/applications.py", line 112, in __call__
    await self.middleware_stack(scope, receive, send)
  File "/usr/local/lib/python3.8/dist-packages/starlette/middleware/errors.py", line 181, in __call__
    raise exc from None
  File "/usr/local/lib/python3.8/dist-packages/starlette/middleware/errors.py", line 159, in __call__
    await self.app(scope, receive, _send)
  File "/usr/local/lib/python3.8/dist-packages/starlette/middleware/cors.py", line 86, in __call__
    await self.simple_response(scope, receive, send, request_headers=headers)
  File "/usr/local/lib/python3.8/dist-packages/starlette/middleware/cors.py", line 142, in simple_response
    await self.app(scope, receive, send)
  File "/usr/local/lib/python3.8/dist-packages/starlette/exceptions.py", line 82, in __call__
    raise exc from None
  File "/usr/local/lib/python3.8/dist-packages/starlette/exceptions.py", line 71, in __call__
    await self.app(scope, receive, sender)
  File "/usr/local/lib/python3.8/dist-packages/starlette/routing.py", line 580, in __call__
    await route.handle(scope, receive, send)
  File "/usr/local/lib/python3.8/dist-packages/starlette/routing.py", line 241, in handle
    await self.app(scope, receive, send)
  File "/usr/local/lib/python3.8/dist-packages/starlette/routing.py", line 52, in app
    response = await func(request)
  File "/usr/local/lib/python3.8/dist-packages/fastapi/routing.py", line 226, in app
    raw_response = await run_endpoint_function(
  File "/usr/local/lib/python3.8/dist-packages/fastapi/routing.py", line 159, in run_endpoint_function
    return await dependant.call(**values)
  File "/root/rcs_api_server/app/routes/set_data.py", line 63, in set_command
    response=requests.post(url, json=command, headers=headers, timeout=2)
  File "/usr/local/lib/python3.8/dist-packages/requests/api.py", line 117, in post
    return request('post', url, data=data, json=json, **kwargs)
  File "/usr/local/lib/python3.8/dist-packages/requests/api.py", line 61, in request
    return session.request(method=method, url=url, **kwargs)
  File "/usr/local/lib/python3.8/dist-packages/requests/sessions.py", line 542, in request
    resp = self.send(prep, **send_kwargs)
  File "/usr/local/lib/python3.8/dist-packages/requests/sessions.py", line 655, in send
    r = adapter.send(request, **kwargs)
  File "/usr/local/lib/python3.8/dist-packages/requests/adapters.py", line 529, in send
    raise ReadTimeout(e, request=request)
requests.exceptions.ReadTimeout: HTTPConnectionPool(host='115.145.177.104', port=1827): Read timed out. (read timeout=2)
ERROR:uvicorn.error:Exception in ASGI application
Traceback (most recent call last):
  File "/usr/local/lib/python3.8/dist-packages/uvicorn/protocols/http/h11_impl.py", line 373, in run_asgi
    result = await app(self.scope, self.receive, self.send)
  File "/usr/local/lib/python3.8/dist-packages/uvicorn/middleware/proxy_headers.py", line 75, in __call__
    return await self.app(scope, receive, send)
  File "/usr/local/lib/python3.8/dist-packages/fastapi/applications.py", line 208, in __call__
    await super().__call__(scope, receive, send)
  File "/usr/local/lib/python3.8/dist-packages/starlette/applications.py", line 112, in __call__
    await self.middleware_stack(scope, receive, send)
  File "/usr/local/lib/python3.8/dist-packages/starlette/middleware/errors.py", line 181, in __call__
    raise exc from None
  File "/usr/local/lib/python3.8/dist-packages/starlette/middleware/errors.py", line 159, in __call__
    await self.app(scope, receive, _send)
  File "/usr/local/lib/python3.8/dist-packages/starlette/middleware/cors.py", line 86, in __call__
    await self.simple_response(scope, receive, send, request_headers=headers)
  File "/usr/local/lib/python3.8/dist-packages/starlette/middleware/cors.py", line 142, in simple_response
    await self.app(scope, receive, send)
  File "/usr/local/lib/python3.8/dist-packages/starlette/exceptions.py", line 82, in __call__
    raise exc from None
  File "/usr/local/lib/python3.8/dist-packages/starlette/exceptions.py", line 71, in __call__
    await self.app(scope, receive, sender)
  File "/usr/local/lib/python3.8/dist-packages/starlette/routing.py", line 580, in __call__
    await route.handle(scope, receive, send)
  File "/usr/local/lib/python3.8/dist-packages/starlette/routing.py", line 241, in handle
    await self.app(scope, receive, send)
  File "/usr/local/lib/python3.8/dist-packages/starlette/routing.py", line 52, in app
    response = await func(request)
  File "/usr/local/lib/python3.8/dist-packages/fastapi/routing.py", line 226, in app
    raw_response = await run_endpoint_function(
  File "/usr/local/lib/python3.8/dist-packages/fastapi/routing.py", line 159, in run_endpoint_function
    return await dependant.call(**values)
  File "/root/rcs_api_server/app/routes/set_data.py", line 63, in set_command
    response=requests.post(url, json=command, headers=headers, timeout=2)
  File "/usr/local/lib/python3.8/dist-packages/requests/api.py", line 117, in post
    return request('post', url, data=data, json=json, **kwargs)
  File "/usr/local/lib/python3.8/dist-packages/requests/api.py", line 61, in request
    return session.request(method=method, url=url, **kwargs)
  File "/usr/local/lib/python3.8/dist-packages/requests/sessions.py", line 542, in request
    resp = self.send(prep, **send_kwargs)
  File "/usr/local/lib/python3.8/dist-packages/requests/sessions.py", line 655, in send
    r = adapter.send(request, **kwargs)
  File "/usr/local/lib/python3.8/dist-packages/requests/adapters.py", line 529, in send
    raise ReadTimeout(e, request=request)
requests.exceptions.ReadTimeout: HTTPConnectionPool(host='115.145.177.104', port=1827): Read timed out. (read timeout=2)
INFO:     115.145.177.104:47396 - "POST /set/robot_data HTTP/1.1" 404 Not Found
INFO:     115.145.177.104:47402 - "POST /set/robot_data HTTP/1.1" 404 Not Found
INFO:     115.145.177.104:47440 - "POST /set/robot_data HTTP/1.1" 404 Not Found
INFO:     115.145.177.104:47446 - "POST /set/robot_data HTTP/1.1" 404 Not Found
INFO:     115.145.177.104:47514 - "POST /set/robot_data HTTP/1.1" 404 Not Found
INFO:     115.145.177.104:47520 - "POST /set/robot_data HTTP/1.1" 404 Not Found
INFO:     185.216.140.186:38852 - "GET http%3A//www.baidu.com/cache/global/img/gs.gif HTTP/1.1" 404 Not Found
INFO:     115.145.177.104:60282 - "GET /hi HTTP/1.1" 404 Not Found
INFO:     115.145.177.104:60284 - "POST /set/robot_data HTTP/1.1" 404 Not Found
INFO:     115.145.177.104:60285 - "POST /set/robot_data HTTP/1.1" 404 Not Found
INFO:     115.145.177.104:42608 - "POST /set/set_command HTTP/1.1" 500 Internal Server Error
ERROR:    Exception in ASGI application
Traceback (most recent call last):
  File "/usr/local/lib/python3.8/dist-packages/uvicorn/protocols/http/h11_impl.py", line 373, in run_asgi
    result = await app(self.scope, self.receive, self.send)
  File "/usr/local/lib/python3.8/dist-packages/uvicorn/middleware/proxy_headers.py", line 75, in __call__
    return await self.app(scope, receive, send)
  File "/usr/local/lib/python3.8/dist-packages/fastapi/applications.py", line 208, in __call__
    await super().__call__(scope, receive, send)
  File "/usr/local/lib/python3.8/dist-packages/starlette/applications.py", line 112, in __call__
    await self.middleware_stack(scope, receive, send)
  File "/usr/local/lib/python3.8/dist-packages/starlette/middleware/errors.py", line 181, in __call__
    raise exc from None
  File "/usr/local/lib/python3.8/dist-packages/starlette/middleware/errors.py", line 159, in __call__
    await self.app(scope, receive, _send)
  File "/usr/local/lib/python3.8/dist-packages/starlette/middleware/cors.py", line 86, in __call__
    await self.simple_response(scope, receive, send, request_headers=headers)
  File "/usr/local/lib/python3.8/dist-packages/starlette/middleware/cors.py", line 142, in simple_response
    await self.app(scope, receive, send)
  File "/usr/local/lib/python3.8/dist-packages/starlette/exceptions.py", line 82, in __call__
    raise exc from None
  File "/usr/local/lib/python3.8/dist-packages/starlette/exceptions.py", line 71, in __call__
    await self.app(scope, receive, sender)
  File "/usr/local/lib/python3.8/dist-packages/starlette/routing.py", line 580, in __call__
    await route.handle(scope, receive, send)
  File "/usr/local/lib/python3.8/dist-packages/starlette/routing.py", line 241, in handle
    await self.app(scope, receive, send)
  File "/usr/local/lib/python3.8/dist-packages/starlette/routing.py", line 52, in app
    response = await func(request)
  File "/usr/local/lib/python3.8/dist-packages/fastapi/routing.py", line 226, in app
    raw_response = await run_endpoint_function(
  File "/usr/local/lib/python3.8/dist-packages/fastapi/routing.py", line 159, in run_endpoint_function
    return await dependant.call(**values)
  File "/root/rcs_api_server/app/routes/set_data.py", line 63, in set_command
    response=requests.post(url, json=command, headers=headers, timeout=2)
  File "/usr/local/lib/python3.8/dist-packages/requests/api.py", line 117, in post
    return request('post', url, data=data, json=json, **kwargs)
  File "/usr/local/lib/python3.8/dist-packages/requests/api.py", line 61, in request
    return session.request(method=method, url=url, **kwargs)
  File "/usr/local/lib/python3.8/dist-packages/requests/sessions.py", line 542, in request
    resp = self.send(prep, **send_kwargs)
  File "/usr/local/lib/python3.8/dist-packages/requests/sessions.py", line 655, in send
    r = adapter.send(request, **kwargs)
  File "/usr/local/lib/python3.8/dist-packages/requests/adapters.py", line 504, in send
    raise ConnectTimeout(e, request=request)
requests.exceptions.ConnectTimeout: HTTPConnectionPool(host='115.145.177.104', port=1828): Max retries exceeded with url: / (Caused by ConnectTimeoutError(<urllib3.connection.HTTPConnection object at 0x7f5874ceb4f0>, 'Connection to 115.145.177.104 timed out. (connect timeout=2)'))
ERROR:uvicorn.error:Exception in ASGI application
Traceback (most recent call last):
  File "/usr/local/lib/python3.8/dist-packages/uvicorn/protocols/http/h11_impl.py", line 373, in run_asgi
    result = await app(self.scope, self.receive, self.send)
  File "/usr/local/lib/python3.8/dist-packages/uvicorn/middleware/proxy_headers.py", line 75, in __call__
    return await self.app(scope, receive, send)
  File "/usr/local/lib/python3.8/dist-packages/fastapi/applications.py", line 208, in __call__
    await super().__call__(scope, receive, send)
  File "/usr/local/lib/python3.8/dist-packages/starlette/applications.py", line 112, in __call__
    await self.middleware_stack(scope, receive, send)
  File "/usr/local/lib/python3.8/dist-packages/starlette/middleware/errors.py", line 181, in __call__
    raise exc from None
  File "/usr/local/lib/python3.8/dist-packages/starlette/middleware/errors.py", line 159, in __call__
    await self.app(scope, receive, _send)
  File "/usr/local/lib/python3.8/dist-packages/starlette/middleware/cors.py", line 86, in __call__
    await self.simple_response(scope, receive, send, request_headers=headers)
  File "/usr/local/lib/python3.8/dist-packages/starlette/middleware/cors.py", line 142, in simple_response
    await self.app(scope, receive, send)
  File "/usr/local/lib/python3.8/dist-packages/starlette/exceptions.py", line 82, in __call__
    raise exc from None
  File "/usr/local/lib/python3.8/dist-packages/starlette/exceptions.py", line 71, in __call__
    await self.app(scope, receive, sender)
  File "/usr/local/lib/python3.8/dist-packages/starlette/routing.py", line 580, in __call__
    await route.handle(scope, receive, send)
  File "/usr/local/lib/python3.8/dist-packages/starlette/routing.py", line 241, in handle
    await self.app(scope, receive, send)
  File "/usr/local/lib/python3.8/dist-packages/starlette/routing.py", line 52, in app
    response = await func(request)
  File "/usr/local/lib/python3.8/dist-packages/fastapi/routing.py", line 226, in app
    raw_response = await run_endpoint_function(
  File "/usr/local/lib/python3.8/dist-packages/fastapi/routing.py", line 159, in run_endpoint_function
    return await dependant.call(**values)
  File "/root/rcs_api_server/app/routes/set_data.py", line 63, in set_command
    response=requests.post(url, json=command, headers=headers, timeout=2)
  File "/usr/local/lib/python3.8/dist-packages/requests/api.py", line 117, in post
    return request('post', url, data=data, json=json, **kwargs)
  File "/usr/local/lib/python3.8/dist-packages/requests/api.py", line 61, in request
    return session.request(method=method, url=url, **kwargs)
  File "/usr/local/lib/python3.8/dist-packages/requests/sessions.py", line 542, in request
    resp = self.send(prep, **send_kwargs)
  File "/usr/local/lib/python3.8/dist-packages/requests/sessions.py", line 655, in send
    r = adapter.send(request, **kwargs)
  File "/usr/local/lib/python3.8/dist-packages/requests/adapters.py", line 504, in send
    raise ConnectTimeout(e, request=request)
requests.exceptions.ConnectTimeout: HTTPConnectionPool(host='115.145.177.104', port=1828): Max retries exceeded with url: / (Caused by ConnectTimeoutError(<urllib3.connection.HTTPConnection object at 0x7f5874ceb4f0>, 'Connection to 115.145.177.104 timed out. (connect timeout=2)'))
INFO:     115.145.177.104:42636 - "POST /set/set_command HTTP/1.1" 500 Internal Server Error
ERROR:    Exception in ASGI application
Traceback (most recent call last):
  File "/usr/local/lib/python3.8/dist-packages/uvicorn/protocols/http/h11_impl.py", line 373, in run_asgi
    result = await app(self.scope, self.receive, self.send)
  File "/usr/local/lib/python3.8/dist-packages/uvicorn/middleware/proxy_headers.py", line 75, in __call__
    return await self.app(scope, receive, send)
  File "/usr/local/lib/python3.8/dist-packages/fastapi/applications.py", line 208, in __call__
    await super().__call__(scope, receive, send)
  File "/usr/local/lib/python3.8/dist-packages/starlette/applications.py", line 112, in __call__
    await self.middleware_stack(scope, receive, send)
  File "/usr/local/lib/python3.8/dist-packages/starlette/middleware/errors.py", line 181, in __call__
    raise exc from None
  File "/usr/local/lib/python3.8/dist-packages/starlette/middleware/errors.py", line 159, in __call__
    await self.app(scope, receive, _send)
  File "/usr/local/lib/python3.8/dist-packages/starlette/middleware/cors.py", line 86, in __call__
    await self.simple_response(scope, receive, send, request_headers=headers)
  File "/usr/local/lib/python3.8/dist-packages/starlette/middleware/cors.py", line 142, in simple_response
    await self.app(scope, receive, send)
  File "/usr/local/lib/python3.8/dist-packages/starlette/exceptions.py", line 82, in __call__
    raise exc from None
  File "/usr/local/lib/python3.8/dist-packages/starlette/exceptions.py", line 71, in __call__
    await self.app(scope, receive, sender)
  File "/usr/local/lib/python3.8/dist-packages/starlette/routing.py", line 580, in __call__
    await route.handle(scope, receive, send)
  File "/usr/local/lib/python3.8/dist-packages/starlette/routing.py", line 241, in handle
    await self.app(scope, receive, send)
  File "/usr/local/lib/python3.8/dist-packages/starlette/routing.py", line 52, in app
    response = await func(request)
  File "/usr/local/lib/python3.8/dist-packages/fastapi/routing.py", line 226, in app
    raw_response = await run_endpoint_function(
  File "/usr/local/lib/python3.8/dist-packages/fastapi/routing.py", line 159, in run_endpoint_function
    return await dependant.call(**values)
  File "/root/rcs_api_server/app/routes/set_data.py", line 63, in set_command
    response=requests.post(url, json=command, headers=headers, timeout=2)
  File "/usr/local/lib/python3.8/dist-packages/requests/api.py", line 117, in post
    return request('post', url, data=data, json=json, **kwargs)
  File "/usr/local/lib/python3.8/dist-packages/requests/api.py", line 61, in request
    return session.request(method=method, url=url, **kwargs)
  File "/usr/local/lib/python3.8/dist-packages/requests/sessions.py", line 542, in request
    resp = self.send(prep, **send_kwargs)
  File "/usr/local/lib/python3.8/dist-packages/requests/sessions.py", line 655, in send
    r = adapter.send(request, **kwargs)
  File "/usr/local/lib/python3.8/dist-packages/requests/adapters.py", line 504, in send
    raise ConnectTimeout(e, request=request)
requests.exceptions.ConnectTimeout: HTTPConnectionPool(host='115.145.177.104', port=1828): Max retries exceeded with url: / (Caused by ConnectTimeoutError(<urllib3.connection.HTTPConnection object at 0x7f5873d1d940>, 'Connection to 115.145.177.104 timed out. (connect timeout=2)'))
ERROR:uvicorn.error:Exception in ASGI application
Traceback (most recent call last):
  File "/usr/local/lib/python3.8/dist-packages/uvicorn/protocols/http/h11_impl.py", line 373, in run_asgi
    result = await app(self.scope, self.receive, self.send)
  File "/usr/local/lib/python3.8/dist-packages/uvicorn/middleware/proxy_headers.py", line 75, in __call__
    return await self.app(scope, receive, send)
  File "/usr/local/lib/python3.8/dist-packages/fastapi/applications.py", line 208, in __call__
    await super().__call__(scope, receive, send)
  File "/usr/local/lib/python3.8/dist-packages/starlette/applications.py", line 112, in __call__
    await self.middleware_stack(scope, receive, send)
  File "/usr/local/lib/python3.8/dist-packages/starlette/middleware/errors.py", line 181, in __call__
    raise exc from None
  File "/usr/local/lib/python3.8/dist-packages/starlette/middleware/errors.py", line 159, in __call__
    await self.app(scope, receive, _send)
  File "/usr/local/lib/python3.8/dist-packages/starlette/middleware/cors.py", line 86, in __call__
    await self.simple_response(scope, receive, send, request_headers=headers)
  File "/usr/local/lib/python3.8/dist-packages/starlette/middleware/cors.py", line 142, in simple_response
    await self.app(scope, receive, send)
  File "/usr/local/lib/python3.8/dist-packages/starlette/exceptions.py", line 82, in __call__
    raise exc from None
  File "/usr/local/lib/python3.8/dist-packages/starlette/exceptions.py", line 71, in __call__
    await self.app(scope, receive, sender)
  File "/usr/local/lib/python3.8/dist-packages/starlette/routing.py", line 580, in __call__
    await route.handle(scope, receive, send)
  File "/usr/local/lib/python3.8/dist-packages/starlette/routing.py", line 241, in handle
    await self.app(scope, receive, send)
  File "/usr/local/lib/python3.8/dist-packages/starlette/routing.py", line 52, in app
    response = await func(request)
  File "/usr/local/lib/python3.8/dist-packages/fastapi/routing.py", line 226, in app
    raw_response = await run_endpoint_function(
  File "/usr/local/lib/python3.8/dist-packages/fastapi/routing.py", line 159, in run_endpoint_function
    return await dependant.call(**values)
  File "/root/rcs_api_server/app/routes/set_data.py", line 63, in set_command
    response=requests.post(url, json=command, headers=headers, timeout=2)
  File "/usr/local/lib/python3.8/dist-packages/requests/api.py", line 117, in post
    return request('post', url, data=data, json=json, **kwargs)
  File "/usr/local/lib/python3.8/dist-packages/requests/api.py", line 61, in request
    return session.request(method=method, url=url, **kwargs)
  File "/usr/local/lib/python3.8/dist-packages/requests/sessions.py", line 542, in request
    resp = self.send(prep, **send_kwargs)
  File "/usr/local/lib/python3.8/dist-packages/requests/sessions.py", line 655, in send
    r = adapter.send(request, **kwargs)
  File "/usr/local/lib/python3.8/dist-packages/requests/adapters.py", line 504, in send
    raise ConnectTimeout(e, request=request)
requests.exceptions.ConnectTimeout: HTTPConnectionPool(host='115.145.177.104', port=1828): Max retries exceeded with url: / (Caused by ConnectTimeoutError(<urllib3.connection.HTTPConnection object at 0x7f5873d1d940>, 'Connection to 115.145.177.104 timed out. (connect timeout=2)'))
INFO:     115.145.177.104:42650 - "POST /set/set_command HTTP/1.1" 200 OK
INFO:     115.145.177.104:42662 - "POST /set/set_command HTTP/1.1" 500 Internal Server Error
ERROR:    Exception in ASGI application
Traceback (most recent call last):
  File "/usr/local/lib/python3.8/dist-packages/uvicorn/protocols/http/h11_impl.py", line 373, in run_asgi
    result = await app(self.scope, self.receive, self.send)
  File "/usr/local/lib/python3.8/dist-packages/uvicorn/middleware/proxy_headers.py", line 75, in __call__
    return await self.app(scope, receive, send)
  File "/usr/local/lib/python3.8/dist-packages/fastapi/applications.py", line 208, in __call__
    await super().__call__(scope, receive, send)
  File "/usr/local/lib/python3.8/dist-packages/starlette/applications.py", line 112, in __call__
    await self.middleware_stack(scope, receive, send)
  File "/usr/local/lib/python3.8/dist-packages/starlette/middleware/errors.py", line 181, in __call__
    raise exc from None
  File "/usr/local/lib/python3.8/dist-packages/starlette/middleware/errors.py", line 159, in __call__
    await self.app(scope, receive, _send)
  File "/usr/local/lib/python3.8/dist-packages/starlette/middleware/cors.py", line 86, in __call__
    await self.simple_response(scope, receive, send, request_headers=headers)
  File "/usr/local/lib/python3.8/dist-packages/starlette/middleware/cors.py", line 142, in simple_response
    await self.app(scope, receive, send)
  File "/usr/local/lib/python3.8/dist-packages/starlette/exceptions.py", line 82, in __call__
    raise exc from None
  File "/usr/local/lib/python3.8/dist-packages/starlette/exceptions.py", line 71, in __call__
    await self.app(scope, receive, sender)
  File "/usr/local/lib/python3.8/dist-packages/starlette/routing.py", line 580, in __call__
    await route.handle(scope, receive, send)
  File "/usr/local/lib/python3.8/dist-packages/starlette/routing.py", line 241, in handle
    await self.app(scope, receive, send)
  File "/usr/local/lib/python3.8/dist-packages/starlette/routing.py", line 52, in app
    response = await func(request)
  File "/usr/local/lib/python3.8/dist-packages/fastapi/routing.py", line 226, in app
    raw_response = await run_endpoint_function(
  File "/usr/local/lib/python3.8/dist-packages/fastapi/routing.py", line 159, in run_endpoint_function
    return await dependant.call(**values)
  File "/root/rcs_api_server/app/routes/set_data.py", line 63, in set_command
    response=requests.post(url, json=command, headers=headers, timeout=2)
  File "/usr/local/lib/python3.8/dist-packages/requests/api.py", line 117, in post
    return request('post', url, data=data, json=json, **kwargs)
  File "/usr/local/lib/python3.8/dist-packages/requests/api.py", line 61, in request
    return session.request(method=method, url=url, **kwargs)
  File "/usr/local/lib/python3.8/dist-packages/requests/sessions.py", line 542, in request
    resp = self.send(prep, **send_kwargs)
  File "/usr/local/lib/python3.8/dist-packages/requests/sessions.py", line 655, in send
    r = adapter.send(request, **kwargs)
  File "/usr/local/lib/python3.8/dist-packages/requests/adapters.py", line 529, in send
    raise ReadTimeout(e, request=request)
requests.exceptions.ReadTimeout: HTTPConnectionPool(host='115.145.177.104', port=1828): Read timed out. (read timeout=2)
ERROR:uvicorn.error:Exception in ASGI application
Traceback (most recent call last):
  File "/usr/local/lib/python3.8/dist-packages/uvicorn/protocols/http/h11_impl.py", line 373, in run_asgi
    result = await app(self.scope, self.receive, self.send)
  File "/usr/local/lib/python3.8/dist-packages/uvicorn/middleware/proxy_headers.py", line 75, in __call__
    return await self.app(scope, receive, send)
  File "/usr/local/lib/python3.8/dist-packages/fastapi/applications.py", line 208, in __call__
    await super().__call__(scope, receive, send)
  File "/usr/local/lib/python3.8/dist-packages/starlette/applications.py", line 112, in __call__
    await self.middleware_stack(scope, receive, send)
  File "/usr/local/lib/python3.8/dist-packages/starlette/middleware/errors.py", line 181, in __call__
    raise exc from None
  File "/usr/local/lib/python3.8/dist-packages/starlette/middleware/errors.py", line 159, in __call__
    await self.app(scope, receive, _send)
  File "/usr/local/lib/python3.8/dist-packages/starlette/middleware/cors.py", line 86, in __call__
    await self.simple_response(scope, receive, send, request_headers=headers)
  File "/usr/local/lib/python3.8/dist-packages/starlette/middleware/cors.py", line 142, in simple_response
    await self.app(scope, receive, send)
  File "/usr/local/lib/python3.8/dist-packages/starlette/exceptions.py", line 82, in __call__
    raise exc from None
  File "/usr/local/lib/python3.8/dist-packages/starlette/exceptions.py", line 71, in __call__
    await self.app(scope, receive, sender)
  File "/usr/local/lib/python3.8/dist-packages/starlette/routing.py", line 580, in __call__
    await route.handle(scope, receive, send)
  File "/usr/local/lib/python3.8/dist-packages/starlette/routing.py", line 241, in handle
    await self.app(scope, receive, send)
  File "/usr/local/lib/python3.8/dist-packages/starlette/routing.py", line 52, in app
    response = await func(request)
  File "/usr/local/lib/python3.8/dist-packages/fastapi/routing.py", line 226, in app
    raw_response = await run_endpoint_function(
  File "/usr/local/lib/python3.8/dist-packages/fastapi/routing.py", line 159, in run_endpoint_function
    return await dependant.call(**values)
  File "/root/rcs_api_server/app/routes/set_data.py", line 63, in set_command
    response=requests.post(url, json=command, headers=headers, timeout=2)
  File "/usr/local/lib/python3.8/dist-packages/requests/api.py", line 117, in post
    return request('post', url, data=data, json=json, **kwargs)
  File "/usr/local/lib/python3.8/dist-packages/requests/api.py", line 61, in request
    return session.request(method=method, url=url, **kwargs)
  File "/usr/local/lib/python3.8/dist-packages/requests/sessions.py", line 542, in request
    resp = self.send(prep, **send_kwargs)
  File "/usr/local/lib/python3.8/dist-packages/requests/sessions.py", line 655, in send
    r = adapter.send(request, **kwargs)
  File "/usr/local/lib/python3.8/dist-packages/requests/adapters.py", line 529, in send
    raise ReadTimeout(e, request=request)
requests.exceptions.ReadTimeout: HTTPConnectionPool(host='115.145.177.104', port=1828): Read timed out. (read timeout=2)
INFO:     115.145.177.104:60291 - "POST /set/robot_data HTTP/1.1" 404 Not Found
INFO:     115.145.177.104:60292 - "POST /set/robot_data HTTP/1.1" 404 Not Found
INFO:     115.145.177.104:60293 - "POST /set/robot_data HTTP/1.1" 404 Not Found
INFO:     115.145.177.104:60294 - "POST /set/robot_data HTTP/1.1" 404 Not Found
INFO:     115.145.177.104:60295 - "POST /set/robot_data HTTP/1.1" 404 Not Found
INFO:     115.145.177.104:60296 - "POST /set/robot_data HTTP/1.1" 404 Not Found
INFO:     115.145.177.104:60297 - "POST /set/robot_data HTTP/1.1" 404 Not Found
INFO:     115.145.177.104:60298 - "POST /set/robot_data HTTP/1.1" 404 Not Found
INFO:     115.145.177.104:60299 - "POST /set/robot_data HTTP/1.1" 404 Not Found
INFO:     115.145.177.104:60300 - "POST /set/robot_data HTTP/1.1" 404 Not Found
INFO:     115.145.177.104:60301 - "POST /set/robot_data HTTP/1.1" 404 Not Found
INFO:     115.145.177.104:60302 - "POST /set/robot_data HTTP/1.1" 404 Not Found
INFO:     115.145.177.104:60303 - "POST /set/robot_data HTTP/1.1" 404 Not Found
INFO:     115.145.177.104:60304 - "POST /set/robot_data HTTP/1.1" 404 Not Found
WARNING:  Invalid HTTP request received.
Traceback (most recent call last):
  File "/usr/local/lib/python3.8/dist-packages/uvicorn/protocols/http/h11_impl.py", line 136, in handle_events
    event = self.conn.next_event()
  File "/usr/local/lib/python3.8/dist-packages/h11/_connection.py", line 443, in next_event
    exc._reraise_as_remote_protocol_error()
  File "/usr/local/lib/python3.8/dist-packages/h11/_util.py", line 76, in _reraise_as_remote_protocol_error
    raise self
  File "/usr/local/lib/python3.8/dist-packages/h11/_connection.py", line 425, in next_event
    event = self._extract_next_receive_event()
  File "/usr/local/lib/python3.8/dist-packages/h11/_connection.py", line 367, in _extract_next_receive_event
    event = self._reader(self._receive_buffer)
  File "/usr/local/lib/python3.8/dist-packages/h11/_readers.py", line 68, in maybe_read_from_IDLE_client
    raise LocalProtocolError("illegal request line")
h11._util.RemoteProtocolError: illegal request line
WARNING:uvicorn.error:Invalid HTTP request received.
Traceback (most recent call last):
  File "/usr/local/lib/python3.8/dist-packages/uvicorn/protocols/http/h11_impl.py", line 136, in handle_events
    event = self.conn.next_event()
  File "/usr/local/lib/python3.8/dist-packages/h11/_connection.py", line 443, in next_event
    exc._reraise_as_remote_protocol_error()
  File "/usr/local/lib/python3.8/dist-packages/h11/_util.py", line 76, in _reraise_as_remote_protocol_error
    raise self
  File "/usr/local/lib/python3.8/dist-packages/h11/_connection.py", line 425, in next_event
    event = self._extract_next_receive_event()
  File "/usr/local/lib/python3.8/dist-packages/h11/_connection.py", line 367, in _extract_next_receive_event
    event = self._reader(self._receive_buffer)
  File "/usr/local/lib/python3.8/dist-packages/h11/_readers.py", line 68, in maybe_read_from_IDLE_client
    raise LocalProtocolError("illegal request line")
h11._util.RemoteProtocolError: illegal request line
INFO:     162.142.125.59:37030 - "GET / HTTP/1.1" 200 OK
INFO:     162.142.125.59:45986 - "GET / HTTP/1.1" 200 OK
INFO:     88.9.119.217:54302 - "GET / HTTP/1.1" 200 OK
WARNING:  Invalid HTTP request received.
Traceback (most recent call last):
  File "/usr/local/lib/python3.8/dist-packages/uvicorn/protocols/http/h11_impl.py", line 136, in handle_events
    event = self.conn.next_event()
  File "/usr/local/lib/python3.8/dist-packages/h11/_connection.py", line 443, in next_event
    exc._reraise_as_remote_protocol_error()
  File "/usr/local/lib/python3.8/dist-packages/h11/_util.py", line 76, in _reraise_as_remote_protocol_error
    raise self
  File "/usr/local/lib/python3.8/dist-packages/h11/_connection.py", line 425, in next_event
    event = self._extract_next_receive_event()
  File "/usr/local/lib/python3.8/dist-packages/h11/_connection.py", line 367, in _extract_next_receive_event
    event = self._reader(self._receive_buffer)
  File "/usr/local/lib/python3.8/dist-packages/h11/_readers.py", line 68, in maybe_read_from_IDLE_client
    raise LocalProtocolError("illegal request line")
h11._util.RemoteProtocolError: illegal request line
WARNING:uvicorn.error:Invalid HTTP request received.
Traceback (most recent call last):
  File "/usr/local/lib/python3.8/dist-packages/uvicorn/protocols/http/h11_impl.py", line 136, in handle_events
    event = self.conn.next_event()
  File "/usr/local/lib/python3.8/dist-packages/h11/_connection.py", line 443, in next_event
    exc._reraise_as_remote_protocol_error()
  File "/usr/local/lib/python3.8/dist-packages/h11/_util.py", line 76, in _reraise_as_remote_protocol_error
    raise self
  File "/usr/local/lib/python3.8/dist-packages/h11/_connection.py", line 425, in next_event
    event = self._extract_next_receive_event()
  File "/usr/local/lib/python3.8/dist-packages/h11/_connection.py", line 367, in _extract_next_receive_event
    event = self._reader(self._receive_buffer)
  File "/usr/local/lib/python3.8/dist-packages/h11/_readers.py", line 68, in maybe_read_from_IDLE_client
    raise LocalProtocolError("illegal request line")
h11._util.RemoteProtocolError: illegal request line
WARNING:  Invalid HTTP request received.
Traceback (most recent call last):
  File "/usr/local/lib/python3.8/dist-packages/uvicorn/protocols/http/h11_impl.py", line 136, in handle_events
    event = self.conn.next_event()
  File "/usr/local/lib/python3.8/dist-packages/h11/_connection.py", line 443, in next_event
    exc._reraise_as_remote_protocol_error()
  File "/usr/local/lib/python3.8/dist-packages/h11/_util.py", line 76, in _reraise_as_remote_protocol_error
    raise self
  File "/usr/local/lib/python3.8/dist-packages/h11/_connection.py", line 425, in next_event
    event = self._extract_next_receive_event()
  File "/usr/local/lib/python3.8/dist-packages/h11/_connection.py", line 367, in _extract_next_receive_event
    event = self._reader(self._receive_buffer)
  File "/usr/local/lib/python3.8/dist-packages/h11/_readers.py", line 68, in maybe_read_from_IDLE_client
    raise LocalProtocolError("illegal request line")
h11._util.RemoteProtocolError: illegal request line
WARNING:uvicorn.error:Invalid HTTP request received.
Traceback (most recent call last):
  File "/usr/local/lib/python3.8/dist-packages/uvicorn/protocols/http/h11_impl.py", line 136, in handle_events
    event = self.conn.next_event()
  File "/usr/local/lib/python3.8/dist-packages/h11/_connection.py", line 443, in next_event
    exc._reraise_as_remote_protocol_error()
  File "/usr/local/lib/python3.8/dist-packages/h11/_util.py", line 76, in _reraise_as_remote_protocol_error
    raise self
  File "/usr/local/lib/python3.8/dist-packages/h11/_connection.py", line 425, in next_event
    event = self._extract_next_receive_event()
  File "/usr/local/lib/python3.8/dist-packages/h11/_connection.py", line 367, in _extract_next_receive_event
    event = self._reader(self._receive_buffer)
  File "/usr/local/lib/python3.8/dist-packages/h11/_readers.py", line 68, in maybe_read_from_IDLE_client
    raise LocalProtocolError("illegal request line")
h11._util.RemoteProtocolError: illegal request line
INFO:     167.248.133.116:51378 - "GET / HTTP/1.1" 200 OK
INFO:     167.248.133.116:43730 - "GET / HTTP/1.1" 200 OK
INFO:     74.82.47.5:38450 - "GET / HTTP/1.1" 200 OK
INFO:     23.90.160.130:45558 - "GET / HTTP/1.1" 200 OK
INFO:     178.32.197.83:37155 - "GET / HTTP/1.1" 200 OK
INFO:     195.154.62.232:51525 - "GET /favicon.ico HTTP/1.1" 404 Not Found
INFO:     172.105.152.112:53832 - "GET /admin/index.php?login HTTP/1.1" 404 Not Found
INFO:     185.173.35.9:44778 - "GET / HTTP/1.1" 200 OK
WARNING:  Invalid HTTP request received.
Traceback (most recent call last):
  File "/usr/local/lib/python3.8/dist-packages/uvicorn/protocols/http/h11_impl.py", line 136, in handle_events
    event = self.conn.next_event()
  File "/usr/local/lib/python3.8/dist-packages/h11/_connection.py", line 443, in next_event
    exc._reraise_as_remote_protocol_error()
  File "/usr/local/lib/python3.8/dist-packages/h11/_util.py", line 76, in _reraise_as_remote_protocol_error
    raise self
  File "/usr/local/lib/python3.8/dist-packages/h11/_connection.py", line 425, in next_event
    event = self._extract_next_receive_event()
  File "/usr/local/lib/python3.8/dist-packages/h11/_connection.py", line 367, in _extract_next_receive_event
    event = self._reader(self._receive_buffer)
  File "/usr/local/lib/python3.8/dist-packages/h11/_readers.py", line 68, in maybe_read_from_IDLE_client
    raise LocalProtocolError("illegal request line")
h11._util.RemoteProtocolError: illegal request line
WARNING:uvicorn.error:Invalid HTTP request received.
Traceback (most recent call last):
  File "/usr/local/lib/python3.8/dist-packages/uvicorn/protocols/http/h11_impl.py", line 136, in handle_events
    event = self.conn.next_event()
  File "/usr/local/lib/python3.8/dist-packages/h11/_connection.py", line 443, in next_event
    exc._reraise_as_remote_protocol_error()
  File "/usr/local/lib/python3.8/dist-packages/h11/_util.py", line 76, in _reraise_as_remote_protocol_error
    raise self
  File "/usr/local/lib/python3.8/dist-packages/h11/_connection.py", line 425, in next_event
    event = self._extract_next_receive_event()
  File "/usr/local/lib/python3.8/dist-packages/h11/_connection.py", line 367, in _extract_next_receive_event
    event = self._reader(self._receive_buffer)
  File "/usr/local/lib/python3.8/dist-packages/h11/_readers.py", line 68, in maybe_read_from_IDLE_client
    raise LocalProtocolError("illegal request line")
h11._util.RemoteProtocolError: illegal request line
WARNING:  Invalid HTTP request received.
Traceback (most recent call last):
  File "/usr/local/lib/python3.8/dist-packages/uvicorn/protocols/http/h11_impl.py", line 136, in handle_events
    event = self.conn.next_event()
  File "/usr/local/lib/python3.8/dist-packages/h11/_connection.py", line 443, in next_event
    exc._reraise_as_remote_protocol_error()
  File "/usr/local/lib/python3.8/dist-packages/h11/_util.py", line 76, in _reraise_as_remote_protocol_error
    raise self
  File "/usr/local/lib/python3.8/dist-packages/h11/_connection.py", line 425, in next_event
    event = self._extract_next_receive_event()
  File "/usr/local/lib/python3.8/dist-packages/h11/_connection.py", line 367, in _extract_next_receive_event
    event = self._reader(self._receive_buffer)
  File "/usr/local/lib/python3.8/dist-packages/h11/_readers.py", line 68, in maybe_read_from_IDLE_client
    raise LocalProtocolError("illegal request line")
h11._util.RemoteProtocolError: illegal request line
WARNING:uvicorn.error:Invalid HTTP request received.
Traceback (most recent call last):
  File "/usr/local/lib/python3.8/dist-packages/uvicorn/protocols/http/h11_impl.py", line 136, in handle_events
    event = self.conn.next_event()
  File "/usr/local/lib/python3.8/dist-packages/h11/_connection.py", line 443, in next_event
    exc._reraise_as_remote_protocol_error()
  File "/usr/local/lib/python3.8/dist-packages/h11/_util.py", line 76, in _reraise_as_remote_protocol_error
    raise self
  File "/usr/local/lib/python3.8/dist-packages/h11/_connection.py", line 425, in next_event
    event = self._extract_next_receive_event()
  File "/usr/local/lib/python3.8/dist-packages/h11/_connection.py", line 367, in _extract_next_receive_event
    event = self._reader(self._receive_buffer)
  File "/usr/local/lib/python3.8/dist-packages/h11/_readers.py", line 68, in maybe_read_from_IDLE_client
    raise LocalProtocolError("illegal request line")
h11._util.RemoteProtocolError: illegal request line
INFO:     180.149.125.173:63180 - "GET /c/ HTTP/1.1" 404 Not Found
INFO:     107.189.11.153:36077 - "GET / HTTP/1.1" 200 OK
INFO:     5.2.73.66:57314 - "GET /favicon.ico HTTP/1.1" 404 Not Found
INFO:     89.248.164.165:36074 - "GET http%3A//www.baidu.com/cache/global/img/gs.gif HTTP/1.1" 404 Not Found
INFO:     46.101.133.105:33052 - "GET / HTTP/1.1" 200 OK
INFO:     180.149.125.166:7911 - "GET / HTTP/1.1" 200 OK
INFO:     74.82.47.3:34422 - "GET / HTTP/1.1" 200 OK
WARNING:  Invalid HTTP request received.
Traceback (most recent call last):
  File "/usr/local/lib/python3.8/dist-packages/uvicorn/protocols/http/h11_impl.py", line 136, in handle_events
    event = self.conn.next_event()
  File "/usr/local/lib/python3.8/dist-packages/h11/_connection.py", line 443, in next_event
    exc._reraise_as_remote_protocol_error()
  File "/usr/local/lib/python3.8/dist-packages/h11/_util.py", line 76, in _reraise_as_remote_protocol_error
    raise self
  File "/usr/local/lib/python3.8/dist-packages/h11/_connection.py", line 425, in next_event
    event = self._extract_next_receive_event()
  File "/usr/local/lib/python3.8/dist-packages/h11/_connection.py", line 367, in _extract_next_receive_event
    event = self._reader(self._receive_buffer)
  File "/usr/local/lib/python3.8/dist-packages/h11/_readers.py", line 68, in maybe_read_from_IDLE_client
    raise LocalProtocolError("illegal request line")
h11._util.RemoteProtocolError: illegal request line
WARNING:uvicorn.error:Invalid HTTP request received.
Traceback (most recent call last):
  File "/usr/local/lib/python3.8/dist-packages/uvicorn/protocols/http/h11_impl.py", line 136, in handle_events
    event = self.conn.next_event()
  File "/usr/local/lib/python3.8/dist-packages/h11/_connection.py", line 443, in next_event
    exc._reraise_as_remote_protocol_error()
  File "/usr/local/lib/python3.8/dist-packages/h11/_util.py", line 76, in _reraise_as_remote_protocol_error
    raise self
  File "/usr/local/lib/python3.8/dist-packages/h11/_connection.py", line 425, in next_event
    event = self._extract_next_receive_event()
  File "/usr/local/lib/python3.8/dist-packages/h11/_connection.py", line 367, in _extract_next_receive_event
    event = self._reader(self._receive_buffer)
  File "/usr/local/lib/python3.8/dist-packages/h11/_readers.py", line 68, in maybe_read_from_IDLE_client
    raise LocalProtocolError("illegal request line")
h11._util.RemoteProtocolError: illegal request line
INFO:     167.248.133.44:55926 - "GET / HTTP/1.1" 200 OK
INFO:     167.248.133.44:39312 - "GET / HTTP/1.1" 200 OK
INFO:     85.202.169.88:43624 - "HEAD / HTTP/1.0" 405 Method Not Allowed
INFO:     167.94.138.115:35124 - "GET / HTTP/1.1" 200 OK
INFO:     167.94.138.115:34452 - "GET / HTTP/1.1" 200 OK
INFO:     199.127.60.104:56744 - "GET / HTTP/1.1" 200 OK
INFO:     65.49.20.69:32714 - "GET / HTTP/1.1" 200 OK
WARNING:  Invalid HTTP request received.
Traceback (most recent call last):
  File "/usr/local/lib/python3.8/dist-packages/uvicorn/protocols/http/h11_impl.py", line 136, in handle_events
    event = self.conn.next_event()
  File "/usr/local/lib/python3.8/dist-packages/h11/_connection.py", line 443, in next_event
    exc._reraise_as_remote_protocol_error()
  File "/usr/local/lib/python3.8/dist-packages/h11/_util.py", line 76, in _reraise_as_remote_protocol_error
    raise self
  File "/usr/local/lib/python3.8/dist-packages/h11/_connection.py", line 425, in next_event
    event = self._extract_next_receive_event()
  File "/usr/local/lib/python3.8/dist-packages/h11/_connection.py", line 367, in _extract_next_receive_event
    event = self._reader(self._receive_buffer)
  File "/usr/local/lib/python3.8/dist-packages/h11/_readers.py", line 68, in maybe_read_from_IDLE_client
    raise LocalProtocolError("illegal request line")
h11._util.RemoteProtocolError: illegal request line
WARNING:uvicorn.error:Invalid HTTP request received.
Traceback (most recent call last):
  File "/usr/local/lib/python3.8/dist-packages/uvicorn/protocols/http/h11_impl.py", line 136, in handle_events
    event = self.conn.next_event()
  File "/usr/local/lib/python3.8/dist-packages/h11/_connection.py", line 443, in next_event
    exc._reraise_as_remote_protocol_error()
  File "/usr/local/lib/python3.8/dist-packages/h11/_util.py", line 76, in _reraise_as_remote_protocol_error
    raise self
  File "/usr/local/lib/python3.8/dist-packages/h11/_connection.py", line 425, in next_event
    event = self._extract_next_receive_event()
  File "/usr/local/lib/python3.8/dist-packages/h11/_connection.py", line 367, in _extract_next_receive_event
    event = self._reader(self._receive_buffer)
  File "/usr/local/lib/python3.8/dist-packages/h11/_readers.py", line 68, in maybe_read_from_IDLE_client
    raise LocalProtocolError("illegal request line")
h11._util.RemoteProtocolError: illegal request line
INFO:     110.10.27.29:58722 - "GET /docs HTTP/1.1" 200 OK
INFO:     110.10.27.29:58722 - "GET /openapi.json HTTP/1.1" 200 OK
